Workbook

Sheet Runbook
B1: FBC Workbook — Adding a New Cup
B2: Runbook for adding a completed FBC (e.g., FBC 13). Most of the workbook updates itself — the manual steps are listed below.
B4: THE 30-SECOND VERSION
B5: Fastest path: in the scoring app press Admin → Export CSV once every match is reported, then hand that file to Claude with the prompt in the README (“Importing a cup with Claude”). Claude runs tools/import_cup.py, which appends the Archives rows, fills the Cups column and checks Data Health. Manual path: paste the new cup’s match results into the Archives tab. The live tabs — Leaderboard, Points, Singles & Doubles records, Rookies, and most of RecordBook — recalculate automatically. Then handle the manual items: add a row for any first-time player, and fill the per-cup input tabs (Cups, Handicaps, Ratings, Cup Info). Finally, ask Claude to recompute CAPA and the analytics tabs.
B7: STEP 1 — ENTER RESULTS IN ARCHIVES
B8: This is the only data entry that drives the automatic tabs.
B9: • Append the new cup’s matches to the bottom of the Archives tab (below the last row).
B10: • Fill the same columns as existing rows: Match #, FBC #, UniqueMatchID (FBC13-D1…, FBC13-S-Name-Name, FBC13-FT), Day, Date (a real Excel date), Geographic Location, Course, Format, Singles/Doubles (exactly Singles, Doubles or FTAS), Captain Size, Team (captain’s surname), Player 1, Player 2 (doubles), handicaps, Points at stake, W/L/T, Points earned, the numeric W / L / T flag columns (1 or 0), and the opponent columns.
B11: • Each head-to-head match = 2 rows (one per side). Whole-field (FTAS) events = one row per player.
B12: • Put the cup number (e.g., 13) in the FBC column, and use W, L, or T (uppercase) for the result.
B14: STEP 2 — ADD A ROW FOR ANY FIRST-TIME PLAYER
B15: A debuting player’s matches still count correctly for everyone else, but the live tabs won’t show the new player until you give them a row.
... B36: REFERENCE — AUTOMATIC vs MANUAL
B37: Tab | C37: On Archives update | D37: Your action
B38: Archives | C38: — | D38: Paste the new cup’s match rows here (Step 1).
B39: Leaderboard | C39: Automatic | D39: Add a row only for a first-time player.
B40: Points | C40: Automatic | D40: FBC 13–15 prebuilt. Add a row for new players; add columns after FBC 15.
B41: Singles_Doubles records | C41: Automatic | D41: Add a row for a new player or a new tandem.
B42: Rookies | C42: Automatic | D42: Add a row for a new player.
B43: RecordBook | C43: Mostly automatic | D43: Margin records (8&7, 5&4, streaks) are entered by hand.
B44: CAPA PPC | C44: Recompute | D44: Ask Claude — regression recalibration.
B45: Sandbagger · Chemistry · Clutch · Pythagorean Luck · Form Guide · MVP Hall of Fame · Nemesis & Patsy · Streak Tracker | C45: Recompute | D45: Ask Claude — computed analytics (same as CAPA).
B46: Cups | C46: Manual | D46: New 1 / 0 / X column each cup.
B47: Handicaps | C47: Manual | D47: New handicap-index column each cup.
B48: Ratings | C48: Manual | D48: New venue-score row each cup.
... B51: Bounties · 7yrFund · Lifetime Mulligans · Cyber Monday · NHI | C51: Manual | D51: Maintain as you always have.
B53: NOTES
B54: • Win % everywhere = (W + ½T) ÷ matches.
B55: • The result column accepts lowercase “t”, but enter “T” for clean data.
B56: • The web app (freddiebcup.streamlit.app) reads UniqueMatchID, Team, Date, Geographic Location, Course, Singles/Doubles and the numeric W / L / T flag columns — fill them all in. A blank UniqueMatchID silently drops the FTAS from the team totals. Only SingleEntity is legacy/unused. The app’s Data Health box (bottom of every page) lists anything it finds wrong after you upload.
B57: • "Live" tabs recompute from Archives automatically. "Computed" tabs — CAPA and the eight analytics tabs — are refreshed by Claude.
B59: Built June 2026 · current through FBC 12.

Sheet Archives
B1: Match # | C1: Match of Session | D1: FBC | E1: UniqueMatchID | F1: Day | G1: Date | H1: AM/PM | I1: Geographic Location | J1: Region | K1: Holes | L1: Front / Back / Full | M1: Course | N1: Tees | O1: Rating | P1: Slope | Q1: Yds | R1: Format | S1: Singles/Doubles | T1: Captain Size | U1: Team | V1: Player 1 | W1: Shirt | X1: Player 1 HCP | Y1: Player 2 | Z1: Player 2 HCP | AA1: Points at stake | AB1: W/L/T | AC1: Result | AD1: Singles Opponent | AE1: SingleEntity | AF1: Points earned | AG1: W | AH1: L | AI1: T | AJ1: W% | AK1: Opponent1 | AL1: Opponent1 Win% | AM1: Opponent2 | AN1: Opponent2 Win%
B2: 1 | C2: 1 | D2: 1 | E2: FBC1-D1 | F2: Saturday | G2: 41447 | H2: AM | I2: Saratoga, NY | J2: Northeast | K2: 9 | L2: Front | M2: Saratoga National | N2: White | O2: 71.3 | P2: 130 | Q2: 6225 | R2: Best Ball | S2: Doubles | T2: Under 6' | U2: Jackson | V2: Grise | W2: White | X2: 15 | Y2: Hickerson | Z2: 20 | AA2: 1 | AB2: W | AC2: 3 & 2 | AE2: =$V2&$Y2 -> GriseHickerson | AF2: 1 | AG2: 1 | AH2: 0 | AI2: 0 | AJ2: 1 | AK2: Hilts | AL2: 0.47321429 | AM2: Lynch | AN2: 0.5546875
B3: 1 | C3: 1 | D3: 1 | E3: FBC1-D1 | F3: Saturday | G3: 41447 | H3: AM | I3: Saratoga, NY | J3: Northeast | K3: 9 | L3: Front | M3: Saratoga National | N3: White | O3: 71.3 | P3: 130 | Q3: 6225 | R3: Best Ball | S3: Doubles | T3: Over 6' | U3: Hilts | V3: Hilts | W3: Red | X3: 18 | Y3: Lynch | Z3: 20 | AA3: 1 | AB3: L | AC3: 3 & 2 | AE3: =$V3&$Y3 -> HiltsLynch | AF3: 0 | AG3: 0 | AH3: 1 | AI3: 0 | AJ3: 0 | AK3: Grise | AL3: 0.546875 | AM3: Hickerson | AN3: 0.35714286
B4: 2 | C4: 2 | D4: 1 | E4: FBC1-D2 | F4: Saturday | G4: 41447 | H4: AM | I4: Saratoga, NY | J4: Northeast | K4: 9 | L4: Front | M4: Saratoga National | N4: White | O4: 71.3 | P4: 130 | Q4: 6225 | R4: Best Ball | S4: Doubles | T4: Under 6' | U4: Jackson | V4: Ferrin | W4: White | X4: 28 | Y4: Jackson | Z4: 15 | AA4: 1 | AB4: W | AC4: 2 & 1 | AE4: =$V4&$Y4 -> FerrinJackson | AF4: 1 | AG4: 1 | AH4: 0 | AI4: 0 | AJ4: 1 | AK4: Macklin | AL4: 0.3 | AM4: Poirier | AN4: 0.48611111
B5: 2 | C5: 2 | D5: 1 | E5: FBC1-D2 | F5: Saturday | G5: 41447 | H5: AM | I5: Saratoga, NY | J5: Northeast | K5: 9 | L5: Front | M5: Saratoga National | N5: White | O5: 71.3 | P5: 130 | Q5: 6225 | R5: Best Ball | S5: Doubles | T5: Over 6' | U5: Hilts | V5: Macklin | W5: Red | X5: 15 | Y5: Poirier | Z5: 10 | AA5: 1 | AB5: L | AC5: 2 & 1 | AE5: =$V5&$Y5 -> MacklinPoirier | AF5: 0 | AG5: 0 | AH5: 1 | AI5: 0 | AJ5: 0 | AK5: Ferrin | AL5: 0.5952381 | AM5: Jackson | AN5: 0.6171875
B6: 3 | C6: 3 | D6: 1 | E6: FBC1-D3 | F6: Saturday | G6: 41447 | H6: AM | I6: Saratoga, NY | J6: Northeast | K6: 9 | L6: Front | M6: Saratoga National | N6: White | O6: 71.3 | P6: 130 | Q6: 6225 | R6: Best Ball | S6: Doubles | T6: Under 6' | U6: Jackson | V6: Flanders | W6: White | X6: 15 | Y6: Mangold | Z6: 15 | AA6: 1 | AB6: L | AC6: 5 & 4 | AE6: =$V6&$Y6 -> FlandersMangold | AF6: 0 | AG6: 0 | AH6: 1 | AI6: 0 | AJ6: 0 | AK6: Connolly | AL6: 0.59375 | AM6: Shively
B7: 3 | C7: 3 | D7: 1 | E7: FBC1-D3 | F7: Saturday | G7: 41447 | H7: AM | I7: Saratoga, NY | J7: Northeast | K7: 9 | L7: Front | M7: Saratoga National | N7: White | O7: 71.3 | P7: 130 | Q7: 6225 | R7: Best Ball | S7: Doubles | T7: Over 6' | U7: Hilts | V7: Connolly | W7: Red | X7: 15 | Y7: Shively | Z7: 30 | AA7: 1 | AB7: W | AC7: 5 & 4 | AE7: =$V7&$Y7 -> ConnollyShively | AF7: 1 | AG7: 1 | AH7: 0 | AI7: 0 | AJ7: 1 | AK7: Flanders | AL7: 0.4296875 | AM7: Mangold | AN7: 0.38392857
B8: 4 | C8: 1 | D8: 1 | E8: FBC1-D4 | F8: Saturday | G8: 41447 | H8: AM | I8: Saratoga, NY | J8: Northeast | K8: 9 | L8: Back | M8: Saratoga National | N8: White | O8: 71.3 | P8: 130 | Q8: 6225 | R8: Scramble | S8: Doubles | T8: Under 6' | U8: Jackson | V8: Grise | W8: White | X8: 15 | Y8: Hickerson | Z8: 20 | AA8: 1 | AB8: T | AC8: Halved | AE8: =$V8&$Y8 -> GriseHickerson | AF8: 0.5 | AG8: 0 | AH8: 0 | AI8: 1 | AJ8: 0.5 | AK8: Hilts | AL8: 0.47321429 | AM8: Lynch | AN8: 0.5546875
B9: 4 | C9: 1 | D9: 1 | E9: FBC1-D4 | F9: Saturday | G9: 41447 | H9: AM | I9: Saratoga, NY | J9: Northeast | K9: 9 | L9: Back | M9: Saratoga National | N9: White | O9: 71.3 | P9: 130 | Q9: 6225 | R9: Scramble | S9: Doubles | T9: Over 6' | U9: Hilts | V9: Hilts | W9: Red | X9: 18 | Y9: Lynch | Z9: 20 | AA9: 1 | AB9: T | AC9: Halved | AE9: =$V9&$Y9 -> HiltsLynch | AF9: 0.5 | AG9: 0 | AH9: 0 | AI9: 1 | AJ9: 0.5 | AK9: Grise | AL9: 0.546875 | AM9: Hickerson | AN9: 0.35714286
B10: 5 | C10: 2 | D10: 1 | E10: FBC1-D5 | F10: Saturday | G10: 41447 | H10: AM | I10: Saratoga, NY | J10: Northeast | K10: 9 | L10: Back | M10: Saratoga National | N10: White | O10: 71.3 | P10: 130 | Q10: 6225 | R10: Scramble | S10: Doubles | T10: Under 6' | U10: Jackson | V10: Ferrin | W10: White | X10: 28 | Y10: Jackson | Z10: 15 | AA10: 1 | AB10: T | AC10: Halved | AE10: =$V10&$Y10 -> FerrinJackson | AF10: 0.5 | AG10: 0 | AH10: 0 | AI10: 1 | AJ10: 0.5 | AK10: Macklin | AL10: 0.3 | AM10: Poirier | AN10: 0.48611111
B11: 5 | C11: 2 | D11: 1 | E11: FBC1-D5 | F11: Saturday | G11: 41447 | H11: AM | I11: Saratoga, NY | J11: Northeast | K11: 9 | L11: Back | M11: Saratoga National | N11: White | O11: 71.3 | P11: 130 | Q11: 6225 | R11: Scramble | S11: Doubles | T11: Over 6' | U11: Hilts | V11: Macklin | W11: Red | X11: 15 | Y11: Poirier | Z11: 10 | AA11: 1 | AB11: T | AC11: Halved | AE11: =$V11&$Y11 -> MacklinPoirier | AF11: 0.5 | AG11: 0 | AH11: 0 | AI11: 1 | AJ11: 0.5 | AK11: Ferrin | AL11: 0.5952381 | AM11: Jackson | AN11: 0.6171875
B12: 6 | C12: 3 | D12: 1 | E12: FBC1-D6 | F12: Saturday | G12: 41447 | H12: AM | I12: Saratoga, NY | J12: Northeast | K12: 9 | L12: Back | M12: Saratoga National | N12: White | O12: 71.3 | P12: 130 | Q12: 6225 | R12: Scramble | S12: Doubles | T12: Under 6' | U12: Jackson | V12: Flanders | W12: White | X12: 15 | Y12: Mangold | Z12: 15 | AA12: 1 | AB12: L | AC12: 1UP | AE12: =$V12&$Y12 -> FlandersMangold | AF12: 0 | AG12: 0 | AH12: 1 | AI12: 0 | AJ12: 0 | AK12: Connolly | AL12: 0.59375 | AM12: Shively
B13: 6 | C13: 3 | D13: 1 | E13: FBC1-D6 | F13: Saturday | G13: 41447 | H13: AM | I13: Saratoga, NY | J13: Northeast | K13: 9 | L13: Back | M13: Saratoga National | N13: White | O13: 71.3 | P13: 130 | Q13: 6225 | R13: Scramble | S13: Doubles | T13: Over 6' | U13: Hilts | V13: Connolly | W13: Red | X13: 15 | Y13: Shively | Z13: 30 | AA13: 1 | AB13: W | AC13: 1UP | AE13: =$V13&$Y13 -> ConnollyShively | AF13: 1 | AG13: 1 | AH13: 0 | AI13: 0 | AJ13: 1 | AK13: Flanders | AL13: 0.4296875 | AM13: Mangold | AN13: 0.38392857
B14: 7 | C14: 1 | D14: 1 | E14: FBC1-D7 | F14: Saturday | G14: 41447 | H14: PM | I14: Saratoga, NY | J14: Northeast | K14: 9 | L14: Front | M14: Saratoga National | N14: White | O14: 71.3 | P14: 130 | Q14: 6225 | R14: Pinehurst | S14: Doubles | T14: Over 6' | U14: Hilts | V14: Macklin | W14: Red | X14: 15 | Y14: Poirier | Z14: 10 | AA14: 1 | AB14: W | AC14: 2 & 1 | AE14: =$V14&$Y14 -> MacklinPoirier | AF14: 1 | AG14: 1 | AH14: 0 | AI14: 0 | AJ14: 1 | AK14: Grise | AL14: 0.546875 | AM14: Hickerson | AN14: 0.35714286
B15: 7 | C15: 1 | D15: 1 | E15: FBC1-D7 | F15: Saturday | G15: 41447 | H15: PM | I15: Saratoga, NY | J15: Northeast | K15: 9 | L15: Front | M15: Saratoga National | N15: White | O15: 71.3 | P15: 130 | Q15: 6225 | R15: Pinehurst | S15: Doubles | T15: Under 6' | U15: Jackson | V15: Grise | W15: White | X15: 15 | Y15: Hickerson | Z15: 20 | AA15: 1 | AB15: L | AC15: 2 & 1 | AE15: =$V15&$Y15 -> GriseHickerson | AF15: 0 | AG15: 0 | AH15: 1 | AI15: 0 | AJ15: 0 | AK15: Macklin | AL15: 0.3 | AM15: Poirier | AN15: 0.48611111
B16: 8 | C16: 2 | D16: 1 | E16: FBC1-D8 | F16: Saturday | G16: 41447 | H16: PM | I16: Saratoga, NY | J16: Northeast | K16: 9 | L16: Front | M16: Saratoga National | N16: White | O16: 71.3 | P16: 130 | Q16: 6225 | R16: Pinehurst | S16: Doubles | T16: Over 6' | U16: Hilts | V16: Hilts | W16: Red | X16: 18 | Y16: Lynch | Z16: 20 | AA16: 1 | AB16: L | AC16: 3 & 2 | AE16: =$V16&$Y16 -> HiltsLynch | AF16: 0 | AG16: 0 | AH16: 1 | AI16: 0 | AJ16: 0 | AK16: Ferrin | AL16: 0.5952381 | AM16: Jackson | AN16: 0.6171875
B17: 8 | C17: 2 | D17: 1 | E17: FBC1-D8 | F17: Saturday | G17: 41447 | H17: PM | I17: Saratoga, NY | J17: Northeast | K17: 9 | L17: Front | M17: Saratoga National | N17: White | O17: 71.3 | P17: 130 | Q17: 6225 | R17: Pinehurst | S17: Doubles | T17: Under 6' | U17: Jackson | V17: Ferrin | W17: White | X17: 28 | Y17: Jackson | Z17: 15 | AA17: 1 | AB17: W | AC17: 3 & 2 | AE17: =$V17&$Y17 -> FerrinJackson | AF17: 1 | AG17: 1 | AH17: 0 | AI17: 0 | AJ17: 1 | AK17: Hilts | AL17: 0.47321429 | AM17: Lynch | AN17: 0.5546875
B18: 9 | C18: 3 | D18: 1 | E18: FBC1-D9 | F18: Saturday | G18: 41447 | H18: PM | I18: Saratoga, NY | J18: Northeast | K18: 9 | L18: Front | M18: Saratoga National | N18: White | O18: 71.3 | P18: 130 | Q18: 6225 | R18: Pinehurst | S18: Doubles | T18: Over 6' | U18: Hilts | V18: Connolly | W18: Red | X18: 15 | Y18: Shively | Z18: 30 | AA18: 1 | AB18: W | AC18: 5 & 4 | AE18: =$V18&$Y18 -> ConnollyShively | AF18: 1 | AG18: 1 | AH18: 0 | AI18: 0 | AJ18: 1 | AK18: Flanders | AL18: 0.4296875 | AM18: Mangold | AN18: 0.38392857
B19: 9 | C19: 3 | D19: 1 | E19: FBC1-D9 | F19: Saturday | G19: 41447 | H19: PM | I19: Saratoga, NY | J19: Northeast | K19: 9 | L19: Front | M19: Saratoga National | N19: White | O19: 71.3 | P19: 130 | Q19: 6225 | R19: Pinehurst | S19: Doubles | T19: Under 6' | U19: Jackson | V19: Flanders | W19: White | X19: 15 | Y19: Mangold | Z19: 15 | AA19: 1 | AB19: L | AC19: 5 & 4 | AE19: =$V19&$Y19 -> FlandersMangold | AF19: 0 | AG19: 0 | AH19: 1 | AI19: 0 | AJ19: 0 | AK19: Connolly | AL19: 0.59375 | AM19: Shively
B20: 10 | C20: 1 | D20: 1 | E20: FBC1-D10 | F20: Saturday | G20: 41447 | H20: PM | I20: Saratoga, NY | J20: Northeast | K20: 9 | L20: Back | M20: Saratoga National | N20: White | O20: 71.3 | P20: 130 | Q20: 6225 | R20: Best Ball | S20: Doubles | T20: Over 6' | U20: Hilts | V20: Macklin | W20: Red | X20: 15 | Y20: Poirier | Z20: 10 | AA20: 1 | AB20: L | AC20: 2 & 1 | AE20: =$V20&$Y20 -> MacklinPoirier | AF20: 0 | AG20: 0 | AH20: 1 | AI20: 0 | AJ20: 0 | AK20: Grise | AL20: 0.546875 | AM20: Hickerson | AN20: 0.35714286
B21: 10 | C21: 1 | D21: 1 | E21: FBC1-D10 | F21: Saturday | G21: 41447 | H21: PM | I21: Saratoga, NY | J21: Northeast | K21: 9 | L21: Back | M21: Saratoga National | N21: White | O21: 71.3 | P21: 130 | Q21: 6225 | R21: Best Ball | S21: Doubles | T21: Under 6' | U21: Jackson | V21: Grise | W21: White | X21: 15 | Y21: Hickerson | Z21: 20 | AA21: 1 | AB21: W | AC21: 2 & 1 | AE21: =$V21&$Y21 -> GriseHickerson | AF21: 1 | AG21: 1 | AH21: 0 | AI21: 0 | AJ21: 1 | AK21: Macklin | AL21: 0.3 | AM21: Poirier | AN21: 0.48611111
B22: 11 | C22: 2 | D22: 1 | E22: FBC1-D11 | F22: Saturday | G22: 41447 | H22: PM | I22: Saratoga, NY | J22: Northeast | K22: 9 | L22: Back | M22: Saratoga National | N22: White | O22: 71.3 | P22: 130 | Q22: 6225 | R22: Best Ball | S22: Doubles | T22: Over 6' | U22: Hilts | V22: Hilts | W22: Red | X22: 18 | Y22: Lynch | Z22: 20 | AA22: 1 | AB22: L | AC22: 2 Up | AE22: =$V22&$Y22 -> HiltsLynch | AF22: 0 | AG22: 0 | AH22: 1 | AI22: 0 | AJ22: 0 | AK22: Ferrin | AL22: 0.5952381 | AM22: Jackson | AN22: 0.6171875
B23: 11 | C23: 2 | D23: 1 | E23: FBC1-D11 | F23: Saturday | G23: 41447 | H23: PM | I23: Saratoga, NY | J23: Northeast | K23: 9 | L23: Back | M23: Saratoga National | N23: White | O23: 71.3 | P23: 130 | Q23: 6225 | R23: Best Ball | S23: Doubles | T23: Under 6' | U23: Jackson | V23: Ferrin | W23: White | X23: 28 | Y23: Jackson | Z23: 15 | AA23: 1 | AB23: W | AC23: 2 Up | AE23: =$V23&$Y23 -> FerrinJackson | AF23: 1 | AG23: 1 | AH23: 0 | AI23: 0 | AJ23: 1 | AK23: Hilts | AL23: 0.47321429 | AM23: Lynch | AN23: 0.5546875
B24: 12 | C24: 3 | D24: 1 | E24: FBC1-D12 | F24: Saturday | G24: 41447 | H24: PM | I24: Saratoga, NY | J24: Northeast | K24: 9 | L24: Back | M24: Saratoga National | N24: White | O24: 71.3 | P24: 130 | Q24: 6225 | R24: Best Ball | S24: Doubles | T24: Over 6' | U24: Hilts | V24: Connolly | W24: Red | X24: 15 | Y24: Shively | Z24: 30 | AA24: 1 | AB24: W | AC24: 3 & 2 | AE24: =$V24&$Y24 -> ConnollyShively | AF24: 1 | AG24: 1 | AH24: 0 | AI24: 0 | AJ24: 1 | AK24: Flanders | AL24: 0.4296875 | AM24: Mangold | AN24: 0.38392857
B25: 12 | C25: 3 | D25: 1 | E25: FBC1-D12 | F25: Saturday | G25: 41447 | H25: PM | I25: Saratoga, NY | J25: Northeast | K25: 9 | L25: Back | M25: Saratoga National | N25: White | O25: 71.3 | P25: 130 | Q25: 6225 | R25: Best Ball | S25: Doubles | T25: Under 6' | U25: Jackson | V25: Flanders | W25: White | X25: 15 | Y25: Mangold | Z25: 15 | AA25: 1 | AB25: L | AC25: 3 & 2 | AE25: =$V25&$Y25 -> FlandersMangold | AF25: 0 | AG25: 0 | AH25: 1 | AI25: 0 | AJ25: 0 | AK25: Connolly | AL25: 0.59375 | AM25: Shively
B26: 13 | C26: 1 | D26: 1 | E26: FBC1-S-Hilts-Mangold | F26: Sunday | G26: 41448 | H26: AM | I26: Saratoga, NY | J26: Northeast | K26: 18 | L26: Full | M26: Saratoga Spa | N26: Blue | O26: 72.2 | P26: 128 | Q26: 6772 | R26: Match Play | S26: Singles | T26: Over 6' | U26: Hilts | V26: Hilts | W26: Blue | X26: 18 | AA26: 2 | AB26: W | AC26: 4 & 3 | AD26: Mangold | AE26: =$V26&$Y26 -> Hilts | AF26: 2 | AG26: 1 | AH26: 0 | AI26: 0 | AJ26: 1 | AK26: Mangold | AL26: 0.38392857
B27: 13 | C27: 1 | D27: 1 | E27: FBC1-S-Hilts-Mangold | F27: Sunday | G27: 41448 | H27: AM | I27: Saratoga, NY | J27: Northeast | K27: 18 | L27: Full | M27: Saratoga Spa | N27: Blue | O27: 72.2 | P27: 128 | Q27: 6772 | R27: Match Play | S27: Singles | T27: Under 6' | U27: Jackson | V27: Mangold | W27: Blue | X27: 15 | AA27: 2 | AB27: L | AC27: 4 & 3 | AD27: Hilts | AE27: =$V27&$Y27 -> Mangold | AF27: 0 | AG27: 0 | AH27: 1 | AI27: 0 | AJ27: 0 | AK27: Hilts | AL27: 0.47321429
B28: 14 | C28: 2 | D28: 1 | E28: FBC1-S-Hickerson-Lynch | F28: Sunday | G28: 41448 | H28: AM | I28: Saratoga, NY | J28: Northeast | K28: 18 | L28: Full | M28: Saratoga Spa | N28: Blue | O28: 72.2 | P28: 128 | Q28: 6772 | R28: Match Play | S28: Singles | T28: Under 6' | U28: Jackson | V28: Hickerson | W28: Blue | X28: 20 | AA28: 2 | AB28: T | AC28: Halved | AD28: Lynch | AE28: =$V28&$Y28 -> Hickerson | AF28: 1 | AG28: 0 | AH28: 0 | AI28: 1 | AJ28: 0.5 | AK28: Lynch | AL28: 0.5546875
B29: 14 | C29: 2 | D29: 1 | E29: FBC1-S-Hickerson-Lynch | F29: Sunday | G29: 41448 | H29: AM | I29: Saratoga, NY | J29: Northeast | K29: 18 | L29: Full | M29: Saratoga Spa | N29: Blue | O29: 72.2 | P29: 128 | Q29: 6772 | R29: Match Play | S29: Singles | T29: Over 6' | U29: Hilts | V29: Lynch | W29: Blue | X29: 20 | AA29: 2 | AB29: T | AC29: Halved | AD29: Hickerson | AE29: =$V29&$Y29 -> Lynch | AF29: 1 | AG29: 0 | AH29: 0 | AI29: 1 | AJ29: 0.5 | AK29: Hickerson | AL29: 0.35714286
B30: 15 | C30: 3 | D30: 1 | E30: FBC1-S-Ferrin-Shively | F30: Sunday | G30: 41448 | H30: AM | I30: Saratoga, NY | J30: Northeast | K30: 18 | L30: Full | M30: Saratoga Spa | N30: Blue | O30: 72.2 | P30: 128 | Q30: 6772 | R30: Match Play | S30: Singles | T30: Over 6' | U30: Hilts | V30: Shively | W30: Blue | X30: 30 | AA30: 2 | AB30: L | AC30: 3 & 2 | AD30: Ferrin | AE30: =$V30&$Y30 -> Shively | AF30: 0 | AG30: 0 | AH30: 1 | AI30: 0 | AJ30: 0 | AK30: Ferrin | AL30: 0.5952381
B31: 15 | C31: 3 | D31: 1 | E31: FBC1-S-Ferrin-Shively | F31: Sunday | G31: 41448 | H31: AM | I31: Saratoga, NY | J31: Northeast | K31: 18 | L31: Full | M31: Saratoga Spa | N31: Blue | O31: 72.2 | P31: 128 | Q31: 6772 | R31: Match Play | S31: Singles | T31: Under 6' | U31: Jackson | V31: Ferrin | W31: Blue | X31: 28 | AA31: 2 | AB31: W | AC31: 3 & 2 | AD31: Shively | AE31: =$V31&$Y31 -> Ferrin | AF31: 2 | AG31: 1 | AH31: 0 | AI31: 0 | AJ31: 1 | AK31: Shively
B32: 16 | C32: 4 | D32: 1 | E32: FBC1-S-Flanders-Macklin | F32: Sunday | G32: 41448 | H32: AM | I32: Saratoga, NY | J32: Northeast | K32: 18 | L32: Full | M32: Saratoga Spa | N32: Blue | O32: 72.2 | P32: 128 | Q32: 6772 | R32: Match Play | S32: Singles | T32: Under 6' | U32: Jackson | V32: Flanders | W32: Blue | X32: 15 | AA32: 2 | AB32: W | AC32: 4 & 3 | AD32: Macklin | AE32: =$V32&$Y32 -> Flanders | AF32: 2 | AG32: 1 | AH32: 0 | AI32: 0 | AJ32: 1 | AK32: Macklin | AL32: 0.3
B33: 16 | C33: 4 | D33: 1 | E33: FBC1-S-Flanders-Macklin | F33: Sunday | G33: 41448 | H33: AM | I33: Saratoga, NY | J33: Northeast | K33: 18 | L33: Full | M33: Saratoga Spa | N33: Blue | O33: 72.2 | P33: 128 | Q33: 6772 | R33: Match Play | S33: Singles | T33: Over 6' | U33: Hilts | V33: Macklin | W33: Blue | X33: 15 | AA33: 2 | AB33: L | AC33: 4 & 3 | AD33: Flanders | AE33: =$V33&$Y33 -> Macklin | AF33: 0 | AG33: 0 | AH33: 1 | AI33: 0 | AJ33: 0 | AK33: Flanders | AL33: 0.4296875
B34: 17 | C34: 5 | D34: 1 | E34: FBC1-S-Connolly-Jackson | F34: Sunday | G34: 41448 | H34: AM | I34: Saratoga, NY | J34: Northeast | K34: 18 | L34: Full | M34: Saratoga Spa | N34: Blue | O34: 72.2 | P34: 128 | Q34: 6772 | R34: Match Play | S34: Singles | T34: Over 6' | U34: Hilts | V34: Connolly | W34: Blue | X34: 15 | AA34: 2 | AB34: W | AC34: 5 & 3 | AD34: Jackson | AE34: =$V34&$Y34 -> Connolly | AF34: 2 | AG34: 1 | AH34: 0 | AI34: 0 | AJ34: 1 | AK34: Jackson | AL34: 0.6171875
B35: 17 | C35: 5 | D35: 1 | E35: FBC1-S-Connolly-Jackson | F35: Sunday | G35: 41448 | H35: AM | I35: Saratoga, NY | J35: Northeast | K35: 18 | L35: Full | M35: Saratoga Spa | N35: Blue | O35: 72.2 | P35: 128 | Q35: 6772 | R35: Match Play | S35: Singles | T35: Under 6' | U35: Jackson | V35: Jackson | W35: Blue | X35: 15 | AA35: 2 | AB35: L | AC35: 5 & 3 | AD35: Connolly | AE35: =$V35&$Y35 -> Jackson | AF35: 0 | AG35: 0 | AH35: 1 | AI35: 0 | AJ35: 0 | AK35: Connolly | AL35: 0.59375
B36: 18 | C36: 6 | D36: 1 | E36: FBC1-S-Grise-Poirier | F36: Sunday | G36: 41448 | H36: AM | I36: Saratoga, NY | J36: Northeast | K36: 18 | L36: Full | M36: Saratoga Spa | N36: Blue | O36: 72.2 | P36: 128 | Q36: 6772 | R36: Match Play | S36: Singles | T36: Under 6' | U36: Jackson | V36: Grise | W36: Blue | X36: 15 | AA36: 2 | AB36: L | AC36: 6 & 5 | AD36: Poirier | AE36: =$V36&$Y36 -> Grise | AF36: 0 | AG36: 0 | AH36: 1 | AI36: 0 | AJ36: 0 | AK36: Poirier | AL36: 0.48611111
B37: 18 | C37: 6 | D37: 1 | E37: FBC1-S-Grise-Poirier | F37: Sunday | G37: 41448 | H37: AM | I37: Saratoga, NY | J37: Northeast | K37: 18 | L37: Full | M37: Saratoga Spa | N37: Blue | O37: 72.2 | P37: 128 | Q37: 6772 | R37: Match Play | S37: Singles | T37: Over 6' | U37: Hilts | V37: Poirier | W37: Blue | X37: 10 | AA37: 2 | AB37: W | AC37: 6 & 5 | AD37: Grise | AE37: =$V37&$Y37 -> Poirier | AF37: 2 | AG37: 1 | AH37: 0 | AI37: 0 | AJ37: 1 | AK37: Grise | AL37: 0.546875
B38: 1 | C38: 1 | D38: 2 | E38: FBC2-D1 | F38: Saturday | G38: 41797 | H38: AM | I38: Verona, NY (Turning Stone) | J38: Northeast | K38: 9 | L38: Front | M38: Atunyote | N38: White | O38: 71.6 | P38: 131 | Q38: 6561 | R38: Best Ball | S38: Doubles | T38: Over 6' | U38: Connolly | V38: Grise | W38: Green | X38: 2 | Y38: Jackson | Z38: 0 | AA38: 1 | AB38: W | AC38: 3 & 1 | AE38: =$V38&$Y38 -> GriseJackson | AF38: 1 | AG38: 1 | AH38: 0 | AI38: 0 | AJ38: 1 | AK38: Bussiculo | AL38: 0.44827586 | AM38: Fogan | AN38: 0.37288136
B39: 1 | C39: 1 | D39: 2 | E39: FBC2-D1 | F39: Saturday | G39: 41797 | H39: AM | I39: Verona, NY (Turning Stone) | J39: Northeast | K39: 9 | L39: Front | M39: Atunyote | N39: White | O39: 71.6 | P39: 131 | Q39: 6561 | R39: Best Ball | S39: Doubles | T39: Over 6' | U39: Ferrin | V39: Bussiculo | W39: Blue/White | X39: 0 | Y39: Fogan | Z39: 22 | AA39: 1 | AB39: L | AC39: 3 & 1 | AE39: =$V39&$Y39 -> BussiculoFogan | AF39: 0 | AG39: 0 | AH39: 1 | AI39: 0 | AJ39: 0 | AK39: Grise | AL39: 0.546875 | AM39: Jackson | AN39: 0.6171875
B40: 2 | C40: 2 | D40: 2 | E40: FBC2-D2 | F40: Saturday | G40: 41797 | H40: AM | I40: Verona, NY (Turning Stone) | J40: Northeast | K40: 9 | L40: Front | M40: Atunyote | N40: White | O40: 71.6 | P40: 131 | Q40: 6561 | R40: Best Ball | S40: Doubles | T40: Over 6' | U40: Ferrin | V40: Ferrin | W40: Blue/White | X40: 12 | Y40: Weisberger | Z40: 5 | AA40: 1 | AB40: T | AC40: Halved | AE40: =$V40&$Y40 -> FerrinWeisberger | AF40: 0.5 | AG40: 0 | AH40: 0 | AI40: 1 | AJ40: 0.5 | AK40: Flanders | AL40: 0.4296875 | AM40: Forster | AN40: 0.59649123
...

Sheet Cups
B2: Player | C2: FBC 1 | D2: FBC 2 | E2: FBC 3 | F2: FBC 4 | G2: FBC 5 | H2: FBC 6 | I2: FBC 7 | J2: FBC 8 | K2: FBC 9 | L2: FBC 10 | M2: FBC 11 | N2: FBC 12 | O2: FBC 13 | P2: Total | Q2: Played | R2: % | S2: Lost
B3: Lynch | C3: 1 | D3: 1 | E3: 1 | F3: 1 | G3: 1 | H3: 1 | I3: 1 | J3: 0 | K3: 1 | L3: 1 | M3: 0 | N3: 1 | O3: 0 | P3: =SUM(C3:O3) -> 10 | Q3: 13 | R3: =P3/Q3 -> 0.76923077 | S3: =Q3-P3 -> 3
B4: Connolly | C4: 1 | D4: 1 | E4: 1 | F4: 1 | G4: 1 | H4: 0 | I4: 0 | J4: 1 | K4: 1 | L4: 1 | M4: 1 | N4: 0 | O4: 1 | P4: =SUM(C4:O4) -> 10 | Q4: 13 | R4: =P4/Q4 -> 0.76923077 | S4: =Q4-P4 -> 3
B5: Grise | C5: 0 | D5: 1 | E5: 0 | F5: 1 | G5: 1 | H5: 1 | I5: 1 | J5: 1 | K5: 0 | L5: 1 | M5: 0 | N5: 1 | O5: 1 | P5: =SUM(C5:O5) -> 9 | Q5: 13 | R5: =P5/Q5 -> 0.69230769 | S5: =Q5-P5 -> 4
B6: Hilts | C6: 1 | D6: 1 | E6: 1 | F6: X | G6: 0 | H6: 1 | I6: 0 | J6: 1 | K6: 1 | L6: 1 | M6: 0 | N6: 1 | O6: 1 | P6: =SUM(C6:O6) -> 9 | Q6: 12 | R6: =P6/Q6 -> 0.75 | S6: =Q6-P6 -> 3
B7: Shively | C7: 1 | D7: 0 | E7: 0 | F7: 1 | G7: 1 | H7: 1 | I7: 0 | J7: 0 | K7: 1 | L7: X | M7: 1 | N7: 1 | O7: 0 | P7: =SUM(C7:O7) -> 7 | Q7: 12 | R7: =P7/Q7 -> 0.58333333 | S7: =Q7-P7 -> 5
B8: Zimmer | C8: X | D8: X | E8: 1 | F8: 1 | G8: 1 | H8: 0 | I8: 1 | J8: 1 | K8: 0 | L8: 0 | M8: 1 | N8: 0 | O8: 1 | P8: =SUM(C8:O8) -> 7 | Q8: 11 | R8: =P8/Q8 -> 0.63636364 | S8: =Q8-P8 -> 4
B9: McInerney | C9: X | D9: X | E9: 1 | F9: 1 | G9: 1 | H9: 1 | I9: 0 | J9: 0 | K9: 1 | L9: 0 | M9: X | N9: X | O9: 0 | P9: =SUM(C9:O9) -> 5 | Q9: 9 | R9: =P9/Q9 -> 0.55555556 | S9: =Q9-P9 -> 4
B10: Flanders | C10: 0 | D10: 1 | E10: 0 | F10: 0 | G10: 0 | H10: 0 | I10: 1 | J10: 0 | K10: 1 | L10: 1 | M10: 0 | N10: 1 | O10: 1 | P10: =SUM(C10:O10) -> 6 | Q10: 13 | R10: =P10/Q10 -> 0.46153846 | S10: =Q10-P10 -> 7
B11: Fogan | C11: X | D11: 0 | E11: 1 | F11: 1 | G11: 0 | H11: 1 | I11: 0 | J11: 0 | K11: 0 | L11: 0 | M11: 1 | N11: 0 | O11: 0 | P11: =SUM(C11:O11) -> 4 | Q11: 12 | R11: =P11/Q11 -> 0.33333333 | S11: =Q11-P11 -> 8
B12: Connors | C12: X | D12: 1 | E12: 0 | F12: 0 | G12: 0 | H12: 0 | I12: 1 | J12: 1 | K12: 1 | L12: 0 | M12: 0 | N12: X | O12: X | P12: =SUM(C12:O12) -> 4 | Q12: 10 | R12: =P12/Q12 -> 0.4 | S12: =Q12-P12 -> 6
B13: Cole | C13: X | D13: 0 | E13: 1 | F13: 0 | G13: 0 | H13: 0 | I13: 1 | J13: 0 | K13: 1 | L13: 1 | M13: 0 | N13: X | O13: 1 | P13: =SUM(C13:O13) -> 5 | Q13: 11 | R13: =P13/Q13 -> 0.45454545 | S13: =Q13-P13 -> 6
B14: Delaney | C14: X | D14: X | E14: X | F14: X | G14: 1 | H14: X | I14: X | J14: 1 | K14: 1 | L14: 1 | M14: 0 | N14: 0 | O14: 1 | P14: =SUM(C14:O14) -> 5 | Q14: 7 | R14: =P14/Q14 -> 0.71428571 | S14: =Q14-P14 -> 2
B15: Gray | C15: X | D15: X | E15: 1 | F15: 0 | G15: 0 | H15: 1 | I15: 1 | J15: X | K15: X | L15: 0 | M15: 1 | N15: X | O15: 0 | P15: =SUM(C15:O15) -> 4 | Q15: 8 | R15: =P15/Q15 -> 0.5 | S15: =Q15-P15 -> 4
B16: Ferrin | C16: 0 | D16: 0 | E16: 0 | F16: 0 | G16: 0 | H16: 0 | I16: 1 | J16: 1 | K16: 0 | L16: 1 | M16: 1 | N16: 0 | O16: 0 | P16: =SUM(C16:O16) -> 4 | Q16: 13 | R16: =P16/Q16 -> 0.30769231 | S16: =Q16-P16 -> 9
B17: Perkins | C17: X | D17: X | E17: X | F17: X | G17: X | H17: X | I17: X | J17: 1 | K17: 1 | L17: 1 | M17: X | N17: 1 | O17: 0 | P17: =SUM(C17:O17) -> 4 | Q17: 5 | R17: =P17/Q17 -> 0.8 | S17: =Q17-P17 -> 1
B18: Forster | C18: X | D18: 1 | E18: 0 | F18: 0 | G18: 1 | H18: 0 | I18: 0 | J18: 0 | K18: 0 | L18: 0 | M18: 1 | N18: 1 | O18: 1 | P18: =SUM(C18:O18) -> 5 | Q18: 12 | R18: =P18/Q18 -> 0.41666667 | S18: =Q18-P18 -> 7
B19: Bussiculo | C19: X | D19: 0 | E19: 0 | F19: 1 | G19: 0 | H19: 1 | I19: 1 | J19: X | K19: X | L19: X | M19: X | N19: X | O19: X | P19: =SUM(C19:O19) -> 3 | Q19: 6 | R19: =P19/Q19 -> 0.5 | S19: =Q19-P19 -> 3
B20: Jackson | C20: 0 | D20: 1 | E20: 0 | F20: 0 | G20: 0 | H20: 1 | I20: 1 | J20: 0 | K20: 0 | L20: 0 | M20: 0 | N20: 0 | O20: 0 | P20: =SUM(C20:O20) -> 3 | Q20: 13 | R20: =P20/Q20 -> 0.23076923 | S20: =Q20-P20 -> 10
B21: Mangold | C21: 0 | D21: 0 | E21: 0 | F21: 0 | G21: 1 | H21: 1 | I21: 0 | J21: 0 | K21: X | L21: 0 | M21: 0 | N21: 1 | O21: 0 | P21: =SUM(C21:O21) -> 3 | Q21: 12 | R21: =P21/Q21 -> 0.25 | S21: =Q21-P21 -> 9
B22: Poirier | C22: 1 | D22: X | E22: X | F22: X | G22: 0 | H22: 0 | I22: 0 | J22: X | K22: 0 | L22: X | M22: 1 | N22: 1 | O22: 1 | P22: =SUM(C22:O22) -> 4 | Q22: 8 | R22: =P22/Q22 -> 0.5 | S22: =Q22-P22 -> 4
B23: Hickerson | C23: 0 | D23: 0 | E23: 1 | F23: 1 | G23: X | H23: X | I23: X | J23: X | K23: X | L23: X | M23: X | N23: X | O23: X | P23: =SUM(C23:O23) -> 2 | Q23: 4 | R23: =P23/Q23 -> 0.5 | S23: =Q23-P23 -> 2
B24: Welker | C24: X | D24: X | E24: X | F24: 1 | G24: 0 | H24: 0 | I24: 0 | J24: 1 | K24: 0 | L24: 0 | M24: 0 | N24: X | O24: 0 | P24: =SUM(C24:O24) -> 2 | Q24: 9 | R24: =P24/Q24 -> 0.22222222 | S24: =Q24-P24 -> 7
B25: Delneky | C25: X | D25: X | E25: X | F25: X | G25: X | H25: X | I25: X | J25: 1 | K25: 0 | L25: 0 | M25: 1 | N25: 0 | O25: 1 | P25: =SUM(C25:O25) -> 3 | Q25: 6 | R25: =P25/Q25 -> 0.5 | S25: =Q25-P25 -> 3
B26: Norat | C26: X | D26: 0 | E26: 0 | F26: 0 | G26: 1 | H26: 0 | I26: 0 | J26: X | K26: X | L26: X | M26: 1 | N26: X | O26: 1 | P26: =SUM(C26:O26) -> 3 | Q26: 8 | R26: =P26/Q26 -> 0.375 | S26: =Q26-P26 -> 5
B27: DeOteris | C27: X | D27: X | E27: X | F27: X | G27: X | H27: X | I27: X | J27: 1 | K27: 0 | L27: X | M27: X | N27: 0 | O27: 0 | P27: =SUM(C27:O27) -> 1 | Q27: 4 | R27: =P27/Q27 -> 0.25 | S27: =Q27-P27 -> 3
B28: Macklin | C28: 1 | D28: X | E28: X | F28: X | G28: X | H28: X | I28: X | J28: X | K28: X | L28: X | M28: X | N28: X | O28: X | P28: =SUM(C28:O28) -> 1 | Q28: 1 | R28: =P28/Q28 -> 1 | S28: =Q28-P28 -> 0
B29: Weisberger | C29: X | D29: 0 | E29: 1 | F29: 0 | G29: X | H29: X | I29: X | J29: X | K29: X | L29: X | M29: X | N29: X | O29: X | P29: =SUM(C29:O29) -> 1 | Q29: 2 | R29: =P29/Q29 -> 0.5 | S29: =Q29-P29 -> 1
B30: R. Connolly | C30: X | D30: X | E30: X | F30: X | G30: X | H30: X | I30: X | J30: X | K30: X | L30: 1 | M30: X | N30: 0 | O30: 1 | P30: =SUM(C30:O30) -> 2 | Q30: 3 | R30: =P30/Q30 -> 0.66666667 | S30: =Q30-P30 -> 1
B31: Snyder | C31: X | D31: X | E31: X | F31: X | G31: X | H31: X | I31: X | J31: X | K31: X | L31: X | M31: X | N31: 1 | O31: X | P31: =SUM(C31:O31) -> 1 | Q31: 1 | R31: =P31/Q31 -> 1 | S31: =Q31-P31 -> 0
B32: Piegari | C32: X | D32: X | E32: X | F32: X | G32: X | H32: X | I32: X | J32: 0 | K32: X | L32: X | M32: X | N32: 0 | O32: 0 | P32: =SUM(C32:O32) -> 0 | Q32: 3 | R32: =P32/Q32 -> 0 | S32: =Q32-P32 -> 3
B33: Ramsay | C33: X | D33: X | E33: X | F33: X | G33: X | H33: X | I33: X | J33: 0 | K33: X | L33: X | M33: X | N33: X | O33: X | P33: =SUM(C33:O33) -> 0 | Q33: 2 | R33: =P33/Q33 -> 0 | S33: =Q33-P33 -> 1
B34: Total | C34: =SUM(C3:C33) -> 6 | D34: =SUM(D3:D33) -> 8 | E34: =SUM(E3:E33) -> 10 | F34: =SUM(F3:F33) -> 10 | G34: =SUM(G3:G33) -> 10 | H34: =SUM(H3:H33) -> 10 | I34: =SUM(I3:I33) -> 10 | J34: =SUM(J3:J33) -> 11 | ... Q34: =SUM(Q3:Q33) -> 256 | S34: =SUM(S3:S33) -> 128
B37: Tab shows whether the players was on the winning team with a "1" meaning they were on the winning team, a "0" meaning they were on the losing team, and "X" meaning they did not participate

Sheet Handicaps
B1: FBC Handicap Index by Cup (master)
B2: Source: Handicaps & Points (Historical) FBC2–13; FBC1 from Archives. 'X' = did not play. Blank = no record.
B3: Player | C3: FBC1 | D3: FBC2 | E3: FBC3 | F3: FBC4 | G3: FBC5 | H3: FBC6 | I3: FBC7 | J3: FBC8 | K3: FBC9 | L3: FBC10 | M3: FBC11 | N3: FBC12 | O3: FBC13 | P3: Average
B4: Bussiculo
B5: Cole | D5: 32.4 | E5: 24.8 | F5: 22 | G5: 18.9 | H5: 20.2 | I5: 17.8 | J5: 15.5 | K5: 15.2 | L5: 16 | M5: 16.5 | N5: X | O5: 16.3 | P5: =IFERROR(AVERAGE(C5:O5),"") -> 19.6
B6: Connolly | C6: 15 | D6: 12.4 | E6: 9.1 | F6: 10.1 | G6: 11.1 | H6: 10.5 | I6: 10.5 | J6: 10.8 | K6: 8.3 | L6: 10.1 | M6: 9.5 | N6: 9.4 | O6: 9.3 | P6: =IFERROR(AVERAGE(C6:O6),"") -> 10.469231
B7: Connors | D7: 18.8 | E7: 16.7 | F7: 16.2 | G7: 15.5 | H7: 15.4 | I7: 16.4 | J7: 17.1 | K7: 18.3 | L7: 17.6 | M7: 17.6 | N7: X | O7: X | P7: =IFERROR(AVERAGE(C7:O7),"") -> 16.96
B8: Delaney | D8: X | E8: X | F8: X | G8: 14.2 | H8: X | I8: X | J8: 11.7 | K8: 10.7 | L8: 11.7 | M8: 9.5 | N8: 11.8 | O8: 14 | P8: =IFERROR(AVERAGE(C8:O8),"") -> 11.942857
B9: Delneky | D9: X | E9: X | F9: X | G9: X | H9: X | I9: X | J9: 17.2 | K9: 18.5 | L9: 18.4 | M9: 17.2 | N9: 17.8 | O9: 17.1 | P9: =IFERROR(AVERAGE(C9:O9),"") -> 17.7
B10: DeOteris | D10: X | E10: X | F10: X | G10: X | H10: X | I10: X | J10: 12.8 | K10: 12.5 | L10: X | M10: X | N10: 12.4 | O10: 11.3 | P10: =IFERROR(AVERAGE(C10:O10),"")
B11: Ferrin | C11: 28 | D11: 22.3 | E11: 19.9 | F11: 17.3 | G11: 15.2 | H11: 14.6 | I11: 14.8 | J11: 12.4 | K11: 13.5 | L11: 12.7 | M11: 10 | N11: 10.1 | O11: 9.8 | P11: =IFERROR(AVERAGE(C11:O11),"") -> 15.430769
B12: Flanders | C12: 15 | D12: 16.8 | E12: 13.4 | F12: 7.8 | G12: 4.6 | H12: 3.9 | I12: 4 | J12: 3.3 | K12: 6.3 | L12: 6.7 | M12: 6.8 | N12: 6.7 | O12: 10.7 | P12: =IFERROR(AVERAGE(C12:O12),"") -> 8.1538462
B13: Fogan | D13: 31.4 | E13: 25 | F13: 27.2 | G13: 26.2 | H13: 25.2 | I13: 23.5 | J13: 18.9 | K13: 19.2 | L13: 19.9 | M13: 18 | N13: 17.4 | O13: 16.6 | P13: =IFERROR(AVERAGE(C13:O13),"") -> 22.375
B14: Forster | D14: 30 | E14: 25 | F14: 22.4 | G14: 19.2 | H14: 15.8 | I14: 16.9 | J14: 15.1 | K14: 12 | L14: 12.7 | M14: 13.1 | N14: 10.9 | O14: 12.1 | P14: =IFERROR(AVERAGE(C14:O14),"") -> 17.1
B15: Gray | D15: X | E15: 11 | F15: 9.4 | G15: 6.8 | H15: 7.5 | I15: 7.3 | J15: X | K15: X | L15: 9 | M15: 8 | N15: X | O15: 8.8 | P15: =IFERROR(AVERAGE(C15:O15),"") -> 8.475
B16: Grise | C16: 15 | D16: 14.1 | E16: 14.7 | F16: 13.1 | G16: 11.8 | H16: 12.5 | I16: 11.9 | J16: 12 | K16: 11.7 | L16: 11.7 | M16: 10.9 | N16: 11.6 | O16: 10.4 | P16: =IFERROR(AVERAGE(C16:O16),"") -> 12.415385
B17: Hickerson | C17: 20 | P17: =IFERROR(AVERAGE(C17:O17),"") -> 20
B18: Hilts | C18: 18 | D18: 18.4 | E18: 17.9 | F18: X | G18: 18.5 | H18: 18.4 | I18: 19.6 | J18: 19.6 | K18: 19.1 | L18: 17.1 | M18: 16.4 | N18: 16 | O18: 16.5 | P18: =IFERROR(AVERAGE(C18:O18),"") -> 17.958333
B19: Jackson | C19: 15 | D19: 12.8 | E19: 12.3 | F19: 12.5 | G19: 12.7 | H19: 12.5 | I19: 11.3 | J19: 9.1 | K19: 8.8 | L19: 8.7 | M19: 9.4 | N19: 7.4 | O19: 8.4 | P19: =IFERROR(AVERAGE(C19:O19),"") -> 10.838462
B20: Lynch | C20: 20 | D20: 18.8 | E20: 16 | F20: 13.9 | G20: 11.8 | H20: 14.4 | I20: 13.4 | J20: 8.9 | K20: 9.3 | L20: 8.7 | M20: 7.9 | N20: 8.9 | O20: 8.5 | P20: =IFERROR(AVERAGE(C20:O20),"") -> 12.346154
B21: Macklin | C21: 15 | P21: =IFERROR(AVERAGE(C21:O21),"") -> 15
B22: Mangold | C22: 15 | D22: 15.7 | E22: 16.4 | F22: 15.9 | G22: 14.3 | H22: 14 | I22: 15.4 | J22: 14.5 | K22: X | L22: 15.9 | M22: 16.2 | N22: 14.7 | O22: 15.2 | P22: =IFERROR(AVERAGE(C22:O22),"") -> 15.266667
B23: McInerney | D23: X | E23: 9.5 | F23: 8.7 | G23: 7.5 | H23: 8.6 | I23: 8.3 | J23: 4.2 | K23: 5.3 | L23: 5.7 | M23: X | N23: X | O23: 4.1 | P23: =IFERROR(AVERAGE(C23:O23),"") -> 6.8777778
B24: Norat | D24: X | E24: 18.7 | F24: 18.2 | G24: 18.6 | H24: 18.9 | I24: 15 | J24: X | K24: X | L24: X | M24: 18 | N24: X | O24: 16.85 | P24: =IFERROR(AVERAGE(C24:O24),"") -> 17.75
B25: Perkins | D25: X | E25: X | F25: X | G25: X | H25: X | I25: X | J25: 5.7 | K25: 8.8 | L25: 6.8 | M25: X | N25: 10.5 | O25: 7.9 | P25: =IFERROR(AVERAGE(C25:O25),"") -> 7.94
B26: Piegari | D26: X | E26: X | F26: X | G26: X | H26: X | I26: X | J26: 10.1 | K26: X | L26: X | M26: X | N26: 9 | O26: 9.9 | P26: =IFERROR(AVERAGE(C26:O26),"") -> 9.6666667
B27: Poirier | C27: 10 | D27: X | E27: X | F27: X | G27: 9.5 | H27: 7.5 | I27: 7.7 | J27: X | K27: 4.5 | L27: X | M27: 5.7 | N27: 4.3 | O27: 5.2 | P27: =IFERROR(AVERAGE(C27:O27),"") -> 6.8
B28: R. Connolly | D28: X | E28: X | F28: X | G28: X | H28: X | I28: X | J28: X | K28: X | L28: 14.6 | M28: X | N28: 12.1 | O28: 10.8 | P28: =IFERROR(AVERAGE(C28:O28),"") -> 12.5
B29: Ramsay
B30: Shively | C30: 30 | D30: 21.8 | E30: 17.7 | F30: 17.3 | G30: 16.5 | H30: 16.2 | I30: 14.6 | J30: 14.6 | K30: 14.4 | L30: X | M30: 12.9 | N30: 12.9 | O30: 13 | P30: =IFERROR(AVERAGE(C30:O30),"") -> 16.825
B31: Snyder
B32: Weisberger
B33: Welker | D33: X | E33: X | F33: 12.7 | G33: 13.6 | H33: 15 | I33: 13.6 | J33: 9 | K33: 9.3 | L33: 10 | M33: 9.5 | N33: X | O33: 13.5 | P33: =IFERROR(AVERAGE(C33:O33),"") -> 11.8
B34: Zimmer | D34: X | E34: 14.3 | F34: 13 | G34: 11.9 | H34: 11.1 | I34: 9.9 | J34: 10.2 | K34: 10.4 | L34: 8.9 | M34: 10.2 | N34: 8.6 | O34: 7.5 | P34: =IFERROR(AVERAGE(C34:O34),"") -> 10.545455

Sheet Points
B1: Points by Cup
B2: Live from Archives. FBC 13–15 columns are pre-built — they auto-populate when those cups are added to Archives.
B4: Player | C4: FBC 1 | D4: FBC 2 | E4: FBC 3 | F4: FBC 4 | G4: FBC 5 | H4: FBC 6 | I4: FBC 7 | J4: FBC 8 | K4: FBC 9 | L4: FBC 10 | M4: FBC 11 | N4: FBC 12 | O4: FBC 13 | P4: FBC 14 | Q4: FBC 15 | R4: Total
B5: Connolly | C5: =SUMIFS(Archives!$AF$2:$AF$1048576,Archives!$D$2:$D$1048576,1,Archives!$V$2:$V$1048576,$B5)+SUMIFS(Archives!$AF$2:$AF$1048576,Archives!$D$2:$D$1048576,1,Archives!$Y$2:$Y$1048576,$B5) -> 6 | D5: =SUMIFS(Archives!$AF$2:$AF$1048576,Archives!$D$2:$D$1048576,2,Archives!$V$2:$V$1048576,$B5)+SUMIFS(Archives!$AF$2:$AF$1048576,Archives!$D$2:$D$1048576,2,Archives!$Y$2:$Y$1048576,$B5) -> 3.5 | E5: =SUMIFS(Archives!$AF$2:$AF$1048576,Archives!$D$2:$D$1048576,3,Archives!$V$2:$V$1048576,$B5)+SUMIFS(Archives!$AF$2:$AF$1048576,Archives!$D$2:$D$1048576,3,Archives!$Y$2:$Y$1048576,$B5) -> 4.5 | F5: =SUMIFS(Archives!$AF$2:$AF$1048576,Archives!$D$2:$D$1048576,4,Archives!$V$2:$V$1048576,$B5)+SUMIFS(Archives!$AF$2:$AF$1048576,Archives!$D$2:$D$1048576,4,Archives!$Y$2:$Y$1048576,$B5) -> 3.5 | G5: =SUMIFS(Archives!$AF$2:$AF$1048576,Archives!$D$2:$D$1048576,5,Archives!$V$2:$V$1048576,$B5)+SUMIFS(Archives!$AF$2:$AF$1048576,Archives!$D$2:$D$1048576,5,Archives!$Y$2:$Y$1048576,$B5) -> 4 | H5: =SUMIFS(Archives!$AF$2:$AF$1048576,Archives!$D$2:$D$1048576,6,Archives!$V$2:$V$1048576,$B5)+SUMIFS(Archives!$AF$2:$AF$1048576,Archives!$D$2:$D$1048576,6,Archives!$Y$2:$Y$1048576,$B5) -> 2 | I5: =SUMIFS(Archives!$AF$2:$AF$1048576,Archives!$D$2:$D$1048576,7,Archives!$V$2:$V$1048576,$B5)+SUMIFS(Archives!$AF$2:$AF$1048576,Archives!$D$2:$D$1048576,7,Archives!$Y$2:$Y$1048576,$B5) -> 2 | J5: =SUMIFS(Archives!$AF$2:$AF$1048576,Archives!$D$2:$D$1048576,8,Archives!$V$2:$V$1048576,$B5)+SUMIFS(Archives!$AF$2:$AF$1048576,Archives!$D$2:$D$1048576,8,Archives!$Y$2:$Y$1048576,$B5) -> 4 | K5: =SUMIFS(Archives!$AF$2:$AF$1048576,Archives!$D$2:$D$1048576,9,Archives!$V$2:$V$1048576,$B5)+SUMIFS(Archives!$AF$2:$AF$1048576,Archives!$D$2:$D$1048576,9,Archives!$Y$2:$Y$1048576,$B5) -> 3.5 | L5: =SUMIFS(Archives!$AF$2:$AF$1048576,Archives!$D$2:$D$1048576,10,Archives!$V$2:$V$1048576,$B5)+SUMIFS(Archives!$AF$2:$AF$1048576,Archives!$D$2:$D$1048576,10,Archives!$Y$2:$Y$1048576,$B5) -> 6 | M5: =SUMIFS(Archives!$AF$2:$AF$1048576,Archives!$D$2:$D$1048576,11,Archives!$V$2:$V$1048576,$B5)+SUMIFS(Archives!$AF$2:$AF$1048576,Archives!$D$2:$D$1048576,11,Archives!$Y$2:$Y$1048576,$B5) -> 5 | N5: =SUMIFS(Archives!$AF$2:$AF$1048576,Archives!$D$2:$D$1048576,12,Archives!$V$2:$V$1048576,$B5)+SUMIFS(Archives!$AF$2:$AF$1048576,Archives!$D$2:$D$1048576,12,Archives!$Y$2:$Y$1048576,$B5) -> 6.5 | O5: =SUMIFS(Archives!$AF$2:$AF$1048576,Archives!$D$2:$D$1048576,13,Archives!$V$2:$V$1048576,$B5)+SUMIFS(Archives!$AF$2:$AF$1048576,Archives!$D$2:$D$1048576,13,Archives!$Y$2:$Y$1048576,$B5) -> 0 | P5: =SUMIFS(Archives!$AF$2:$AF$1048576,Archives!$D$2:$D$1048576,14,Archives!$V$2:$V$1048576,$B5)+SUMIFS(Archives!$AF$2:$AF$1048576,Archives!$D$2:$D$1048576,14,Archives!$Y$2:$Y$1048576,$B5) -> 0 | Q5: =SUMIFS(Archives!$AF$2:$AF$1048576,Archives!$D$2:$D$1048576,15,Archives!$V$2:$V$1048576,$B5)+SUMIFS(Archives!$AF$2:$AF$1048576,Archives!$D$2:$D$1048576,15,Archives!$Y$2:$Y$1048576,$B5) -> 0 | R5: =SUM(C5:Q5) -> 50.5
B6: Ferrin | C6: =SUMIFS(Archives!$AF$2:$AF$1048576,Archives!$D$2:$D$1048576,1,Archives!$V$2:$V$1048576,$B6)+SUMIFS(Archives!$AF$2:$AF$1048576,Archives!$D$2:$D$1048576,1,Archives!$Y$2:$Y$1048576,$B6) -> 5.5 | D6: =SUMIFS(Archives!$AF$2:$AF$1048576,Archives!$D$2:$D$1048576,2,Archives!$V$2:$V$1048576,$B6)+SUMIFS(Archives!$AF$2:$AF$1048576,Archives!$D$2:$D$1048576,2,Archives!$Y$2:$Y$1048576,$B6) -> 2.5 | E6: =SUMIFS(Archives!$AF$2:$AF$1048576,Archives!$D$2:$D$1048576,3,Archives!$V$2:$V$1048576,$B6)+SUMIFS(Archives!$AF$2:$AF$1048576,Archives!$D$2:$D$1048576,3,Archives!$Y$2:$Y$1048576,$B6) -> 5 | F6: =SUMIFS(Archives!$AF$2:$AF$1048576,Archives!$D$2:$D$1048576,4,Archives!$V$2:$V$1048576,$B6)+SUMIFS(Archives!$AF$2:$AF$1048576,Archives!$D$2:$D$1048576,4,Archives!$Y$2:$Y$1048576,$B6) -> 2.5 | G6: =SUMIFS(Archives!$AF$2:$AF$1048576,Archives!$D$2:$D$1048576,5,Archives!$V$2:$V$1048576,$B6)+SUMIFS(Archives!$AF$2:$AF$1048576,Archives!$D$2:$D$1048576,5,Archives!$Y$2:$Y$1048576,$B6) -> 4.5 | H6: =SUMIFS(Archives!$AF$2:$AF$1048576,Archives!$D$2:$D$1048576,6,Archives!$V$2:$V$1048576,$B6)+SUMIFS(Archives!$AF$2:$AF$1048576,Archives!$D$2:$D$1048576,6,Archives!$Y$2:$Y$1048576,$B6) -> 3 | I6: =SUMIFS(Archives!$AF$2:$AF$1048576,Archives!$D$2:$D$1048576,7,Archives!$V$2:$V$1048576,$B6)+SUMIFS(Archives!$AF$2:$AF$1048576,Archives!$D$2:$D$1048576,7,Archives!$Y$2:$Y$1048576,$B6) -> 4.5 | J6: =SUMIFS(Archives!$AF$2:$AF$1048576,Archives!$D$2:$D$1048576,8,Archives!$V$2:$V$1048576,$B6)+SUMIFS(Archives!$AF$2:$AF$1048576,Archives!$D$2:$D$1048576,8,Archives!$Y$2:$Y$1048576,$B6) -> 3.5 | K6: =SUMIFS(Archives!$AF$2:$AF$1048576,Archives!$D$2:$D$1048576,9,Archives!$V$2:$V$1048576,$B6)+SUMIFS(Archives!$AF$2:$AF$1048576,Archives!$D$2:$D$1048576,9,Archives!$Y$2:$Y$1048576,$B6) -> 2.5 | L6: =SUMIFS(Archives!$AF$2:$AF$1048576,Archives!$D$2:$D$1048576,10,Archives!$V$2:$V$1048576,$B6)+SUMIFS(Archives!$AF$2:$AF$1048576,Archives!$D$2:$D$1048576,10,Archives!$Y$2:$Y$1048576,$B6) -> 4 | M6: =SUMIFS(Archives!$AF$2:$AF$1048576,Archives!$D$2:$D$1048576,11,Archives!$V$2:$V$1048576,$B6)+SUMIFS(Archives!$AF$2:$AF$1048576,Archives!$D$2:$D$1048576,11,Archives!$Y$2:$Y$1048576,$B6) -> 5 | N6: =SUMIFS(Archives!$AF$2:$AF$1048576,Archives!$D$2:$D$1048576,12,Archives!$V$2:$V$1048576,$B6)+SUMIFS(Archives!$AF$2:$AF$1048576,Archives!$D$2:$D$1048576,12,Archives!$Y$2:$Y$1048576,$B6) -> 3.5 | O6: =SUMIFS(Archives!$AF$2:$AF$1048576,Archives!$D$2:$D$1048576,13,Archives!$V$2:$V$1048576,$B6)+SUMIFS(Archives!$AF$2:$AF$1048576,Archives!$D$2:$D$1048576,13,Archives!$Y$2:$Y$1048576,$B6) -> 0 | P6: =SUMIFS(Archives!$AF$2:$AF$1048576,Archives!$D$2:$D$1048576,14,Archives!$V$2:$V$1048576,$B6)+SUMIFS(Archives!$AF$2:$AF$1048576,Archives!$D$2:$D$1048576,14,Archives!$Y$2:$Y$1048576,$B6) -> 0 | Q6: =SUMIFS(Archives!$AF$2:$AF$1048576,Archives!$D$2:$D$1048576,15,Archives!$V$2:$V$1048576,$B6)+SUMIFS(Archives!$AF$2:$AF$1048576,Archives!$D$2:$D$1048576,15,Archives!$Y$2:$Y$1048576,$B6) -> 0 | R6: =SUM(C6:Q6) -> 46
B7: Jackson | C7: =SUMIFS(Archives!$AF$2:$AF$1048576,Archives!$D$2:$D$1048576,1,Archives!$V$2:$V$1048576,$B7)+SUMIFS(Archives!$AF$2:$AF$1048576,Archives!$D$2:$D$1048576,1,Archives!$Y$2:$Y$1048576,$B7) -> 3.5 | D7: =SUMIFS(Archives!$AF$2:$AF$1048576,Archives!$D$2:$D$1048576,2,Archives!$V$2:$V$1048576,$B7)+SUMIFS(Archives!$AF$2:$AF$1048576,Archives!$D$2:$D$1048576,2,Archives!$Y$2:$Y$1048576,$B7) -> 6 | E7: =SUMIFS(Archives!$AF$2:$AF$1048576,Archives!$D$2:$D$1048576,3,Archives!$V$2:$V$1048576,$B7)+SUMIFS(Archives!$AF$2:$AF$1048576,Archives!$D$2:$D$1048576,3,Archives!$Y$2:$Y$1048576,$B7) -> 5 | F7: =SUMIFS(Archives!$AF$2:$AF$1048576,Archives!$D$2:$D$1048576,4,Archives!$V$2:$V$1048576,$B7)+SUMIFS(Archives!$AF$2:$AF$1048576,Archives!$D$2:$D$1048576,4,Archives!$Y$2:$Y$1048576,$B7) -> 2.5 | G7: =SUMIFS(Archives!$AF$2:$AF$1048576,Archives!$D$2:$D$1048576,5,Archives!$V$2:$V$1048576,$B7)+SUMIFS(Archives!$AF$2:$AF$1048576,Archives!$D$2:$D$1048576,5,Archives!$Y$2:$Y$1048576,$B7) -> 3.5 | H7: =SUMIFS(Archives!$AF$2:$AF$1048576,Archives!$D$2:$D$1048576,6,Archives!$V$2:$V$1048576,$B7)+SUMIFS(Archives!$AF$2:$AF$1048576,Archives!$D$2:$D$1048576,6,Archives!$Y$2:$Y$1048576,$B7) -> 6.5 | I7: =SUMIFS(Archives!$AF$2:$AF$1048576,Archives!$D$2:$D$1048576,7,Archives!$V$2:$V$1048576,$B7)+SUMIFS(Archives!$AF$2:$AF$1048576,Archives!$D$2:$D$1048576,7,Archives!$Y$2:$Y$1048576,$B7) -> 4 | J7: =SUMIFS(Archives!$AF$2:$AF$1048576,Archives!$D$2:$D$1048576,8,Archives!$V$2:$V$1048576,$B7)+SUMIFS(Archives!$AF$2:$AF$1048576,Archives!$D$2:$D$1048576,8,Archives!$Y$2:$Y$1048576,$B7) -> 2.5 | K7: =SUMIFS(Archives!$AF$2:$AF$1048576,Archives!$D$2:$D$1048576,9,Archives!$V$2:$V$1048576,$B7)+SUMIFS(Archives!$AF$2:$AF$1048576,Archives!$D$2:$D$1048576,9,Archives!$Y$2:$Y$1048576,$B7) -> 1 | L7: =SUMIFS(Archives!$AF$2:$AF$1048576,Archives!$D$2:$D$1048576,10,Archives!$V$2:$V$1048576,$B7)+SUMIFS(Archives!$AF$2:$AF$1048576,Archives!$D$2:$D$1048576,10,Archives!$Y$2:$Y$1048576,$B7) -> 5.5 | M7: =SUMIFS(Archives!$AF$2:$AF$1048576,Archives!$D$2:$D$1048576,11,Archives!$V$2:$V$1048576,$B7)+SUMIFS(Archives!$AF$2:$AF$1048576,Archives!$D$2:$D$1048576,11,Archives!$Y$2:$Y$1048576,$B7) -> 2.5 | N7: =SUMIFS(Archives!$AF$2:$AF$1048576,Archives!$D$2:$D$1048576,12,Archives!$V$2:$V$1048576,$B7)+SUMIFS(Archives!$AF$2:$AF$1048576,Archives!$D$2:$D$1048576,12,Archives!$Y$2:$Y$1048576,$B7) -> 3.5 | O7: =SUMIFS(Archives!$AF$2:$AF$1048576,Archives!$D$2:$D$1048576,13,Archives!$V$2:$V$1048576,$B7)+SUMIFS(Archives!$AF$2:$AF$1048576,Archives!$D$2:$D$1048576,13,Archives!$Y$2:$Y$1048576,$B7) -> 0 | P7: =SUMIFS(Archives!$AF$2:$AF$1048576,Archives!$D$2:$D$1048576,14,Archives!$V$2:$V$1048576,$B7)+SUMIFS(Archives!$AF$2:$AF$1048576,Archives!$D$2:$D$1048576,14,Archives!$Y$2:$Y$1048576,$B7) -> 0 | Q7: =SUMIFS(Archives!$AF$2:$AF$1048576,Archives!$D$2:$D$1048576,15,Archives!$V$2:$V$1048576,$B7)+SUMIFS(Archives!$AF$2:$AF$1048576,Archives!$D$2:$D$1048576,15,Archives!$Y$2:$Y$1048576,$B7) -> 0 | R7: =SUM(C7:Q7) -> 46
B8: Grise | C8: =SUMIFS(Archives!$AF$2:$AF$1048576,Archives!$D$2:$D$1048576,1,Archives!$V$2:$V$1048576,$B8)+SUMIFS(Archives!$AF$2:$AF$1048576,Archives!$D$2:$D$1048576,1,Archives!$Y$2:$Y$1048576,$B8) -> 2.5 | D8: =SUMIFS(Archives!$AF$2:$AF$1048576,Archives!$D$2:$D$1048576,2,Archives!$V$2:$V$1048576,$B8)+SUMIFS(Archives!$AF$2:$AF$1048576,Archives!$D$2:$D$1048576,2,Archives!$Y$2:$Y$1048576,$B8) -> 5 | E8: =SUMIFS(Archives!$AF$2:$AF$1048576,Archives!$D$2:$D$1048576,3,Archives!$V$2:$V$1048576,$B8)+SUMIFS(Archives!$AF$2:$AF$1048576,Archives!$D$2:$D$1048576,3,Archives!$Y$2:$Y$1048576,$B8) -> 1 | F8: =SUMIFS(Archives!$AF$2:$AF$1048576,Archives!$D$2:$D$1048576,4,Archives!$V$2:$V$1048576,$B8)+SUMIFS(Archives!$AF$2:$AF$1048576,Archives!$D$2:$D$1048576,4,Archives!$Y$2:$Y$1048576,$B8) -> 5 | G8: =SUMIFS(Archives!$AF$2:$AF$1048576,Archives!$D$2:$D$1048576,5,Archives!$V$2:$V$1048576,$B8)+SUMIFS(Archives!$AF$2:$AF$1048576,Archives!$D$2:$D$1048576,5,Archives!$Y$2:$Y$1048576,$B8) -> 2.5 | H8: =SUMIFS(Archives!$AF$2:$AF$1048576,Archives!$D$2:$D$1048576,6,Archives!$V$2:$V$1048576,$B8)+SUMIFS(Archives!$AF$2:$AF$1048576,Archives!$D$2:$D$1048576,6,Archives!$Y$2:$Y$1048576,$B8) -> 4.5 | I8: =SUMIFS(Archives!$AF$2:$AF$1048576,Archives!$D$2:$D$1048576,7,Archives!$V$2:$V$1048576,$B8)+SUMIFS(Archives!$AF$2:$AF$1048576,Archives!$D$2:$D$1048576,7,Archives!$Y$2:$Y$1048576,$B8) -> 6.5 | J8: =SUMIFS(Archives!$AF$2:$AF$1048576,Archives!$D$2:$D$1048576,8,Archives!$V$2:$V$1048576,$B8)+SUMIFS(Archives!$AF$2:$AF$1048576,Archives!$D$2:$D$1048576,8,Archives!$Y$2:$Y$1048576,$B8) -> 4.5 | K8: =SUMIFS(Archives!$AF$2:$AF$1048576,Archives!$D$2:$D$1048576,9,Archives!$V$2:$V$1048576,$B8)+SUMIFS(Archives!$AF$2:$AF$1048576,Archives!$D$2:$D$1048576,9,Archives!$Y$2:$Y$1048576,$B8) -> 2 | L8: =SUMIFS(Archives!$AF$2:$AF$1048576,Archives!$D$2:$D$1048576,10,Archives!$V$2:$V$1048576,$B8)+SUMIFS(Archives!$AF$2:$AF$1048576,Archives!$D$2:$D$1048576,10,Archives!$Y$2:$Y$1048576,$B8) -> 5 | M8: =SUMIFS(Archives!$AF$2:$AF$1048576,Archives!$D$2:$D$1048576,11,Archives!$V$2:$V$1048576,$B8)+SUMIFS(Archives!$AF$2:$AF$1048576,Archives!$D$2:$D$1048576,11,Archives!$Y$2:$Y$1048576,$B8) -> 0.5 | N8: =SUMIFS(Archives!$AF$2:$AF$1048576,Archives!$D$2:$D$1048576,12,Archives!$V$2:$V$1048576,$B8)+SUMIFS(Archives!$AF$2:$AF$1048576,Archives!$D$2:$D$1048576,12,Archives!$Y$2:$Y$1048576,$B8) -> 4 | O8: =SUMIFS(Archives!$AF$2:$AF$1048576,Archives!$D$2:$D$1048576,13,Archives!$V$2:$V$1048576,$B8)+SUMIFS(Archives!$AF$2:$AF$1048576,Archives!$D$2:$D$1048576,13,Archives!$Y$2:$Y$1048576,$B8) -> 0 | P8: =SUMIFS(Archives!$AF$2:$AF$1048576,Archives!$D$2:$D$1048576,14,Archives!$V$2:$V$1048576,$B8)+SUMIFS(Archives!$AF$2:$AF$1048576,Archives!$D$2:$D$1048576,14,Archives!$Y$2:$Y$1048576,$B8) -> 0 | Q8: =SUMIFS(Archives!$AF$2:$AF$1048576,Archives!$D$2:$D$1048576,15,Archives!$V$2:$V$1048576,$B8)+SUMIFS(Archives!$AF$2:$AF$1048576,Archives!$D$2:$D$1048576,15,Archives!$Y$2:$Y$1048576,$B8) -> 0 | R8: =SUM(C8:Q8) -> 43
B9: Forster | C9: =SUMIFS(Archives!$AF$2:$AF$1048576,Archives!$D$2:$D$1048576,1,Archives!$V$2:$V$1048576,$B9)+SUMIFS(Archives!$AF$2:$AF$1048576,Archives!$D$2:$D$1048576,1,Archives!$Y$2:$Y$1048576,$B9) -> 0 | D9: =SUMIFS(Archives!$AF$2:$AF$1048576,Archives!$D$2:$D$1048576,2,Archives!$V$2:$V$1048576,$B9)+SUMIFS(Archives!$AF$2:$AF$1048576,Archives!$D$2:$D$1048576,2,Archives!$Y$2:$Y$1048576,$B9) -> 5.5 | E9: =SUMIFS(Archives!$AF$2:$AF$1048576,Archives!$D$2:$D$1048576,3,Archives!$V$2:$V$1048576,$B9)+SUMIFS(Archives!$AF$2:$AF$1048576,Archives!$D$2:$D$1048576,3,Archives!$Y$2:$Y$1048576,$B9) -> 3.5 | F9: =SUMIFS(Archives!$AF$2:$AF$1048576,Archives!$D$2:$D$1048576,4,Archives!$V$2:$V$1048576,$B9)+SUMIFS(Archives!$AF$2:$AF$1048576,Archives!$D$2:$D$1048576,4,Archives!$Y$2:$Y$1048576,$B9) -> 5.5 | G9: =SUMIFS(Archives!$AF$2:$AF$1048576,Archives!$D$2:$D$1048576,5,Archives!$V$2:$V$1048576,$B9)+SUMIFS(Archives!$AF$2:$AF$1048576,Archives!$D$2:$D$1048576,5,Archives!$Y$2:$Y$1048576,$B9) -> 5 | H9: =SUMIFS(Archives!$AF$2:$AF$1048576,Archives!$D$2:$D$1048576,6,Archives!$V$2:$V$1048576,$B9)+SUMIFS(Archives!$AF$2:$AF$1048576,Archives!$D$2:$D$1048576,6,Archives!$Y$2:$Y$1048576,$B9) -> 5 | I9: =SUMIFS(Archives!$AF$2:$AF$1048576,Archives!$D$2:$D$1048576,7,Archives!$V$2:$V$1048576,$B9)+SUMIFS(Archives!$AF$2:$AF$1048576,Archives!$D$2:$D$1048576,7,Archives!$Y$2:$Y$1048576,$B9) -> 4.5 | J9: =SUMIFS(Archives!$AF$2:$AF$1048576,Archives!$D$2:$D$1048576,8,Archives!$V$2:$V$1048576,$B9)+SUMIFS(Archives!$AF$2:$AF$1048576,Archives!$D$2:$D$1048576,8,Archives!$Y$2:$Y$1048576,$B9) -> 1 | K9: =SUMIFS(Archives!$AF$2:$AF$1048576,Archives!$D$2:$D$1048576,9,Archives!$V$2:$V$1048576,$B9)+SUMIFS(Archives!$AF$2:$AF$1048576,Archives!$D$2:$D$1048576,9,Archives!$Y$2:$Y$1048576,$B9) -> 4.5 | L9: =SUMIFS(Archives!$AF$2:$AF$1048576,Archives!$D$2:$D$1048576,10,Archives!$V$2:$V$1048576,$B9)+SUMIFS(Archives!$AF$2:$AF$1048576,Archives!$D$2:$D$1048576,10,Archives!$Y$2:$Y$1048576,$B9) -> 0 | M9: =SUMIFS(Archives!$AF$2:$AF$1048576,Archives!$D$2:$D$1048576,11,Archives!$V$2:$V$1048576,$B9)+SUMIFS(Archives!$AF$2:$AF$1048576,Archives!$D$2:$D$1048576,11,Archives!$Y$2:$Y$1048576,$B9) -> 3.5 | N9: =SUMIFS(Archives!$AF$2:$AF$1048576,Archives!$D$2:$D$1048576,12,Archives!$V$2:$V$1048576,$B9)+SUMIFS(Archives!$AF$2:$AF$1048576,Archives!$D$2:$D$1048576,12,Archives!$Y$2:$Y$1048576,$B9) -> 4 | O9: =SUMIFS(Archives!$AF$2:$AF$1048576,Archives!$D$2:$D$1048576,13,Archives!$V$2:$V$1048576,$B9)+SUMIFS(Archives!$AF$2:$AF$1048576,Archives!$D$2:$D$1048576,13,Archives!$Y$2:$Y$1048576,$B9) -> 0 | P9: =SUMIFS(Archives!$AF$2:$AF$1048576,Archives!$D$2:$D$1048576,14,Archives!$V$2:$V$1048576,$B9)+SUMIFS(Archives!$AF$2:$AF$1048576,Archives!$D$2:$D$1048576,14,Archives!$Y$2:$Y$1048576,$B9) -> 0 | Q9: =SUMIFS(Archives!$AF$2:$AF$1048576,Archives!$D$2:$D$1048576,15,Archives!$V$2:$V$1048576,$B9)+SUMIFS(Archives!$AF$2:$AF$1048576,Archives!$D$2:$D$1048576,15,Archives!$Y$2:$Y$1048576,$B9) -> 0 | R9: =SUM(C9:Q9) -> 42
B10: Lynch | C10: =SUMIFS(Archives!$AF$2:$AF$1048576,Archives!$D$2:$D$1048576,1,Archives!$V$2:$V$1048576,$B10)+SUMIFS(Archives!$AF$2:$AF$1048576,Archives!$D$2:$D$1048576,1,Archives!$Y$2:$Y$1048576,$B10) -> 1.5 | D10: =SUMIFS(Archives!$AF$2:$AF$1048576,Archives!$D$2:$D$1048576,2,Archives!$V$2:$V$1048576,$B10)+SUMIFS(Archives!$AF$2:$AF$1048576,Archives!$D$2:$D$1048576,2,Archives!$Y$2:$Y$1048576,$B10) -> 4 | E10: =SUMIFS(Archives!$AF$2:$AF$1048576,Archives!$D$2:$D$1048576,3,Archives!$V$2:$V$1048576,$B10)+SUMIFS(Archives!$AF$2:$AF$1048576,Archives!$D$2:$D$1048576,3,Archives!$Y$2:$Y$1048576,$B10) -> 4 | F10: =SUMIFS(Archives!$AF$2:$AF$1048576,Archives!$D$2:$D$1048576,4,Archives!$V$2:$V$1048576,$B10)+SUMIFS(Archives!$AF$2:$AF$1048576,Archives!$D$2:$D$1048576,4,Archives!$Y$2:$Y$1048576,$B10) -> 4 | G10: =SUMIFS(Archives!$AF$2:$AF$1048576,Archives!$D$2:$D$1048576,5,Archives!$V$2:$V$1048576,$B10)+SUMIFS(Archives!$AF$2:$AF$1048576,Archives!$D$2:$D$1048576,5,Archives!$Y$2:$Y$1048576,$B10) -> 3.5 | H10: =SUMIFS(Archives!$AF$2:$AF$1048576,Archives!$D$2:$D$1048576,6,Archives!$V$2:$V$1048576,$B10)+SUMIFS(Archives!$AF$2:$AF$1048576,Archives!$D$2:$D$1048576,6,Archives!$Y$2:$Y$1048576,$B10) -> 1.5 | I10: =SUMIFS(Archives!$AF$2:$AF$1048576,Archives!$D$2:$D$1048576,7,Archives!$V$2:$V$1048576,$B10)+SUMIFS(Archives!$AF$2:$AF$1048576,Archives!$D$2:$D$1048576,7,Archives!$Y$2:$Y$1048576,$B10) -> 4.5 | J10: =SUMIFS(Archives!$AF$2:$AF$1048576,Archives!$D$2:$D$1048576,8,Archives!$V$2:$V$1048576,$B10)+SUMIFS(Archives!$AF$2:$AF$1048576,Archives!$D$2:$D$1048576,8,Archives!$Y$2:$Y$1048576,$B10) -> 4 | K10: =SUMIFS(Archives!$AF$2:$AF$1048576,Archives!$D$2:$D$1048576,9,Archives!$V$2:$V$1048576,$B10)+SUMIFS(Archives!$AF$2:$AF$1048576,Archives!$D$2:$D$1048576,9,Archives!$Y$2:$Y$1048576,$B10) -> 5.5 | L10: =SUMIFS(Archives!$AF$2:$AF$1048576,Archives!$D$2:$D$1048576,10,Archives!$V$2:$V$1048576,$B10)+SUMIFS(Archives!$AF$2:$AF$1048576,Archives!$D$2:$D$1048576,10,Archives!$Y$2:$Y$1048576,$B10) -> 3.5 | M10: =SUMIFS(Archives!$AF$2:$AF$1048576,Archives!$D$2:$D$1048576,11,Archives!$V$2:$V$1048576,$B10)+SUMIFS(Archives!$AF$2:$AF$1048576,Archives!$D$2:$D$1048576,11,Archives!$Y$2:$Y$1048576,$B10) -> 2 | N10: =SUMIFS(Archives!$AF$2:$AF$1048576,Archives!$D$2:$D$1048576,12,Archives!$V$2:$V$1048576,$B10)+SUMIFS(Archives!$AF$2:$AF$1048576,Archives!$D$2:$D$1048576,12,Archives!$Y$2:$Y$1048576,$B10) -> 3 | O10: =SUMIFS(Archives!$AF$2:$AF$1048576,Archives!$D$2:$D$1048576,13,Archives!$V$2:$V$1048576,$B10)+SUMIFS(Archives!$AF$2:$AF$1048576,Archives!$D$2:$D$1048576,13,Archives!$Y$2:$Y$1048576,$B10) -> 0 | P10: =SUMIFS(Archives!$AF$2:$AF$1048576,Archives!$D$2:$D$1048576,14,Archives!$V$2:$V$1048576,$B10)+SUMIFS(Archives!$AF$2:$AF$1048576,Archives!$D$2:$D$1048576,14,Archives!$Y$2:$Y$1048576,$B10) -> 0 | Q10: =SUMIFS(Archives!$AF$2:$AF$1048576,Archives!$D$2:$D$1048576,15,Archives!$V$2:$V$1048576,$B10)+SUMIFS(Archives!$AF$2:$AF$1048576,Archives!$D$2:$D$1048576,15,Archives!$Y$2:$Y$1048576,$B10) -> 0 | R10: =SUM(C10:Q10) -> 41
B11: Flanders | C11: =SUMIFS(Archives!$AF$2:$AF$1048576,Archives!$D$2:$D$1048576,1,Archives!$V$2:$V$1048576,$B11)+SUMIFS(Archives!$AF$2:$AF$1048576,Archives!$D$2:$D$1048576,1,Archives!$Y$2:$Y$1048576,$B11) -> 2 | D11: =SUMIFS(Archives!$AF$2:$AF$1048576,Archives!$D$2:$D$1048576,2,Archives!$V$2:$V$1048576,$B11)+SUMIFS(Archives!$AF$2:$AF$1048576,Archives!$D$2:$D$1048576,2,Archives!$Y$2:$Y$1048576,$B11) -> 1.5 | E11: =SUMIFS(Archives!$AF$2:$AF$1048576,Archives!$D$2:$D$1048576,3,Archives!$V$2:$V$1048576,$B11)+SUMIFS(Archives!$AF$2:$AF$1048576,Archives!$D$2:$D$1048576,3,Archives!$Y$2:$Y$1048576,$B11) -> 0.5 | F11: =SUMIFS(Archives!$AF$2:$AF$1048576,Archives!$D$2:$D$1048576,4,Archives!$V$2:$V$1048576,$B11)+SUMIFS(Archives!$AF$2:$AF$1048576,Archives!$D$2:$D$1048576,4,Archives!$Y$2:$Y$1048576,$B11) -> 5.5 | G11: =SUMIFS(Archives!$AF$2:$AF$1048576,Archives!$D$2:$D$1048576,5,Archives!$V$2:$V$1048576,$B11)+SUMIFS(Archives!$AF$2:$AF$1048576,Archives!$D$2:$D$1048576,5,Archives!$Y$2:$Y$1048576,$B11) -> 3 | H11: =SUMIFS(Archives!$AF$2:$AF$1048576,Archives!$D$2:$D$1048576,6,Archives!$V$2:$V$1048576,$B11)+SUMIFS(Archives!$AF$2:$AF$1048576,Archives!$D$2:$D$1048576,6,Archives!$Y$2:$Y$1048576,$B11) -> 3 | I11: =SUMIFS(Archives!$AF$2:$AF$1048576,Archives!$D$2:$D$1048576,7,Archives!$V$2:$V$1048576,$B11)+SUMIFS(Archives!$AF$2:$AF$1048576,Archives!$D$2:$D$1048576,7,Archives!$Y$2:$Y$1048576,$B11) -> 4 | J11: =SUMIFS(Archives!$AF$2:$AF$1048576,Archives!$D$2:$D$1048576,8,Archives!$V$2:$V$1048576,$B11)+SUMIFS(Archives!$AF$2:$AF$1048576,Archives!$D$2:$D$1048576,8,Archives!$Y$2:$Y$1048576,$B11) -> 3 | K11: =SUMIFS(Archives!$AF$2:$AF$1048576,Archives!$D$2:$D$1048576,9,Archives!$V$2:$V$1048576,$B11)+SUMIFS(Archives!$AF$2:$AF$1048576,Archives!$D$2:$D$1048576,9,Archives!$Y$2:$Y$1048576,$B11) -> 2 | L11: =SUMIFS(Archives!$AF$2:$AF$1048576,Archives!$D$2:$D$1048576,10,Archives!$V$2:$V$1048576,$B11)+SUMIFS(Archives!$AF$2:$AF$1048576,Archives!$D$2:$D$1048576,10,Archives!$Y$2:$Y$1048576,$B11) -> 4 | M11: =SUMIFS(Archives!$AF$2:$AF$1048576,Archives!$D$2:$D$1048576,11,Archives!$V$2:$V$1048576,$B11)+SUMIFS(Archives!$AF$2:$AF$1048576,Archives!$D$2:$D$1048576,11,Archives!$Y$2:$Y$1048576,$B11) -> 1.5 | N11: =SUMIFS(Archives!$AF$2:$AF$1048576,Archives!$D$2:$D$1048576,12,Archives!$V$2:$V$1048576,$B11)+SUMIFS(Archives!$AF$2:$AF$1048576,Archives!$D$2:$D$1048576,12,Archives!$Y$2:$Y$1048576,$B11) -> 6.5 | O11: =SUMIFS(Archives!$AF$2:$AF$1048576,Archives!$D$2:$D$1048576,13,Archives!$V$2:$V$1048576,$B11)+SUMIFS(Archives!$AF$2:$AF$1048576,Archives!$D$2:$D$1048576,13,Archives!$Y$2:$Y$1048576,$B11) -> 0 | P11: =SUMIFS(Archives!$AF$2:$AF$1048576,Archives!$D$2:$D$1048576,14,Archives!$V$2:$V$1048576,$B11)+SUMIFS(Archives!$AF$2:$AF$1048576,Archives!$D$2:$D$1048576,14,Archives!$Y$2:$Y$1048576,$B11) -> 0 | Q11: =SUMIFS(Archives!$AF$2:$AF$1048576,Archives!$D$2:$D$1048576,15,Archives!$V$2:$V$1048576,$B11)+SUMIFS(Archives!$AF$2:$AF$1048576,Archives!$D$2:$D$1048576,15,Archives!$Y$2:$Y$1048576,$B11) -> 0 | R11: =SUM(C11:Q11) -> 36.5
