Workbook

Sheet Handicaps
B2: Player | C2: FBC 2 | D2: FBC 3 | E2: FBC 4 | F2: FBC 5 | G2: FBC 6 | H2: FBC 7 | I2: FBC 8 | J2: FBC 9 | K2: FBC 10 | L2: FBC 11 | M2: FBC 12 | N2: FBC 13 | P2: Average | Q2: SD | R2: High | S2: Low | T2: Delta
B3: Cole | C3: 32.4 | D3: 24.8 | E3: 22 | F3: 18.9 | G3: 20.2 | H3: 17.8 | I3: 15.5 | J3: 15.2 | K3: 16 | L3: 16.5 | M3: X | N3: 16.3 | P3: =AVERAGE(C3:N3) -> 19.6 | Q3: =STDEV(C3:N3) -> 5.1996154 | R3: =MAX(C3:N3) -> 32.4 | S3: =MIN(C3:N3) -> 15.2 | T3: =R3-S3 -> 17.2
B4: Connolly, B | C4: 12.4 | D4: 9.1 | E4: 10.1 | F4: 11.1 | G4: 10.5 | H4: 10.5 | I4: 10.8 | J4: 8.3 | K4: 10.1 | L4: 9.5 | M4: 9.4 | N4: 9.3 | P4: =AVERAGE(C4:N4) -> 10.091667 | Q4: =STDEV(C4:N4) -> 1.0799481 | R4: =MAX(C4:N4) -> 12.4 | S4: =MIN(C4:N4) -> 8.3 | T4: =R4-S4 -> 4.1
B5: Connolly, R | C5: X | D5: X | E5: X | F5: X | G5: X | H5: X | I5: X | J5: X | K5: 14.6 | L5: X | M5: 12.1 | N5: 10.8 | P5: =AVERAGE(C5:N5) -> 12.5 | Q5: =STDEV(C5:N5) -> 1.9313208 | R5: =MAX(C5:N5) -> 14.6 | S5: =MIN(C5:N5) -> 10.8 | T5: =R5-S5 -> 3.8
B6: Connors | C6: 18.8 | D6: 16.7 | E6: 16.2 | F6: 15.5 | G6: 15.4 | H6: 16.4 | I6: 17.1 | J6: 18.3 | K6: 17.6 | L6: 17.6 | M6: X | N6: X | P6: =AVERAGE(C6:N6) -> 16.96 | Q6: =STDEV(C6:N6) -> 1.1325487 | R6: =MAX(C6:N6) -> 18.8 | S6: =MIN(C6:N6) -> 15.4 | T6: =R6-S6 -> 3.4
B7: Delaney | C7: X | D7: X | E7: X | F7: 14.2 | G7: X | H7: X | I7: 11.7 | J7: 10.7 | K7: 11.7 | L7: 9.5 | M7: 11.8 | N7: 14 | P7: =AVERAGE(C7:N7) -> 11.942857 | Q7: =STDEV(C7:N7) -> 1.6821188 | R7: =MAX(C7:N7) -> 14.2 | S7: =MIN(C7:N7) -> 9.5 | T7: =R7-S7 -> 4.7
B8: Delneky | C8: X | D8: X | E8: X | F8: X | G8: X | H8: X | I8: 17.2 | J8: 18.5 | K8: 18.4 | L8: 17.2 | M8: 17.8 | N8: 17.1 | P8: =AVERAGE(C8:N8) -> 17.7 | Q8: =STDEV(C8:N8) -> 0.63245553 | R8: =MAX(C8:N8) -> 18.5 | S8: =MIN(C8:N8) -> 17.1 | T8: =R8-S8 -> 1.4
B9: DeOteris | C9: X | D9: X | E9: X | F9: X | G9: X | H9: X | I9: 12.8 | J9: 12.5 | K9: X | L9: X | M9: 12.4 | N9: 11.3 | P9: =AVERAGE(C9:N9) | Q9: =STDEV(C9:N9) | R9: =MAX(C9:N9) | S9: =MIN(C9:N9) | T9: =R9-S9
B10: Ferrin | C10: 22.3 | D10: 19.9 | E10: 17.3 | F10: 15.2 | G10: 14.6 | H10: 14.8 | I10: 12.4 | J10: 13.5 | K10: 12.7 | L10: 10 | M10: 10.1 | N10: 9.8 | P10: =AVERAGE(C10:N10) -> 14.383333 | Q10: =STDEV(C10:N10) -> 3.9151996 | R10: =MAX(C10:N10) -> 22.3 | S10: =MIN(C10:N10) -> 9.8 | T10: =R10-S10 -> 12.5
B11: Flanders | C11: 16.8 | D11: 13.4 | E11: 7.8 | F11: 4.6 | G11: 3.9 | H11: 4 | I11: 3.3 | J11: 6.3 | K11: 6.7 | L11: 6.8 | M11: 6.7 | N11: 10.7 | P11: =AVERAGE(C11:N11) -> 7.5833333 | Q11: =STDEV(C11:N11) -> 4.1122507 | R11: =MAX(C11:N11) -> 16.8 | S11: =MIN(C11:N11) -> 3.3 | T11: =R11-S11 -> 13.5
B12: Fogan | C12: 31.4 | D12: 25 | E12: 27.2 | F12: 26.2 | G12: 25.2 | H12: 23.5 | I12: 18.9 | J12: 19.2 | K12: 19.9 | L12: 18 | M12: 17.4 | N12: 16.6 | P12: =AVERAGE(C12:N12) -> 22.375 | Q12: =STDEV(C12:N12) -> 4.6809333 | R12: =MAX(C12:N12) -> 31.4 | S12: =MIN(C12:N12) -> 16.6 | T12: =R12-S12 -> 14.8
B13: Forster | C13: 30 | D13: 25 | E13: 22.4 | F13: 19.2 | G13: 15.8 | H13: 16.9 | I13: 15.1 | J13: 12 | K13: 12.7 | L13: 13.1 | M13: 10.9 | N13: 12.1 | P13: =AVERAGE(C13:N13) -> 17.1 | Q13: =STDEV(C13:N13) -> 5.968554 | R13: =MAX(C13:N13) -> 30 | S13: =MIN(C13:N13) -> 10.9 | T13: =R13-S13 -> 19.1
B14: Gray | C14: X | D14: 11 | E14: 9.4 | F14: 6.8 | G14: 7.5 | H14: 7.3 | I14: X | J14: X | K14: 9 | L14: 8 | M14: X | N14: 8.8 | P14: =AVERAGE(C14:N14) -> 8.475 | Q14: =STDEV(C14:N14) -> 1.3614593 | R14: =MAX(C14:N14) -> 11 | S14: =MIN(C14:N14) -> 6.8 | T14: =R14-S14 -> 4.2
B15: Grise | C15: 14.1 | D15: 14.7 | E15: 13.1 | F15: 11.8 | G15: 12.5 | H15: 11.9 | I15: 12 | J15: 11.7 | K15: 11.7 | L15: 10.9 | M15: 11.6 | N15: 10.4 | P15: =AVERAGE(C15:N15) -> 12.2 | Q15: =STDEV(C15:N15) -> 1.2372991 | R15: =MAX(C15:N15) -> 14.7 | S15: =MIN(C15:N15) -> 10.4 | T15: =R15-S15 -> 4.3
B16: Hilts | C16: 18.4 | D16: 17.9 | E16: X | F16: 18.5 | G16: 18.4 | H16: 19.6 | I16: 19.6 | J16: 19.1 | K16: 17.1 | L16: 16.4 | M16: 16 | N16: 16.5 | P16: =AVERAGE(C16:N16) -> 17.954545 | Q16: =STDEV(C16:N16) -> 1.2848063 | R16: =MAX(C16:N16) -> 19.6 | S16: =MIN(C16:N16) -> 16 | T16: =R16-S16 -> 3.6
B17: Jackson | C17: 12.8 | D17: 12.3 | E17: 12.5 | F17: 12.7 | G17: 12.5 | H17: 11.3 | I17: 9.1 | J17: 8.8 | K17: 8.7 | L17: 9.4 | M17: 7.4 | N17: 8.4 | P17: =AVERAGE(C17:N17) -> 10.491667 | Q17: =STDEV(C17:N17) -> 2.0299836 | R17: =MAX(C17:N17) -> 12.8 | S17: =MIN(C17:N17) -> 7.4 | T17: =R17-S17 -> 5.4
B18: Lynch | C18: 18.8 | D18: 16 | E18: 13.9 | F18: 11.8 | G18: 14.4 | H18: 13.4 | I18: 8.9 | J18: 9.3 | K18: 8.7 | L18: 7.9 | M18: 8.9 | N18: 8.5 | P18: =AVERAGE(C18:N18) -> 11.708333 | Q18: =STDEV(C18:N18) -> 3.555395 | R18: =MAX(C18:N18) -> 18.8 | S18: =MIN(C18:N18) -> 7.9 | T18: =R18-S18 -> 10.9
B19: Mangold | C19: 15.7 | D19: 16.4 | E19: 15.9 | F19: 14.3 | G19: 14 | H19: 15.4 | I19: 14.5 | J19: X | K19: 15.9 | L19: 16.2 | M19: 14.7 | N19: 15.2 | P19: =AVERAGE(C19:N19) -> 15.290909 | Q19: =STDEV(C19:N19) -> 0.81296315 | R19: =MAX(C19:N19) -> 16.4 | S19: =MIN(C19:N19) -> 14 | T19: =R19-S19 -> 2.4
B20: McInerney | C20: X | D20: 9.5 | E20: 8.7 | F20: 7.5 | G20: 8.6 | H20: 8.3 | I20: 4.2 | J20: 5.3 | K20: 5.7 | L20: X | M20: X | N20: 4.1 | P20: =AVERAGE(C20:N20) -> 6.8777778 | Q20: =STDEV(C20:N20) -> 2.0717009 | R20: =MAX(C20:N20) -> 9.5 | S20: =MIN(C20:N20) -> 4.1 | T20: =R20-S20 -> 5.4
B21: Norat | C21: X | D21: 18.7 | E21: 18.2 | F21: 18.6 | G21: 18.9 | H21: 15 | I21: X | J21: X | K21: X | L21: 18 | M21: X | N21: 16.85 | P21: =AVERAGE(C21:N21) -> 17.75 | Q21: =STDEV(C21:N21) -> 1.3895443 | R21: =MAX(C21:N21) -> 18.9 | S21: =MIN(C21:N21) -> 15 | T21: =R21-S21 -> 3.9
B22: Perkins | C22: X | D22: X | E22: X | F22: X | G22: X | H22: X | I22: 5.7 | J22: 8.8 | K22: 6.8 | L22: X | M22: 10.5 | N22: 7.9 | P22: =AVERAGE(C22:N22) -> 7.94 | Q22: =STDEV(C22:N22) -> 1.8447222 | R22: =MAX(C22:N22) -> 10.5 | S22: =MIN(C22:N22) -> 5.7 | T22: =R22-S22 -> 4.8
B23: Piegari | C23: X | D23: X | E23: X | F23: X | G23: X | H23: X | I23: 10.1 | J23: X | K23: X | L23: X | M23: 9 | N23: 9.9 | P23: =AVERAGE(C23:N23) -> 9.6666667 | Q23: =STDEV(C23:N23) -> 0.58594653 | R23: =MAX(C23:N23) -> 10.1 | S23: =MIN(C23:N23) -> 9 | T23: =R23-S23 -> 1.1
B24: Poirier | C24: X | D24: X | E24: X | F24: 9.5 | G24: 7.5 | H24: 7.7 | I24: X | J24: 4.5 | K24: X | L24: 5.7 | M24: 4.3 | N24: 5.2 | P24: =AVERAGE(C24:N24) -> 6.3428571 | Q24: =STDEV(C24:N24) -> 1.9337848 | R24: =MAX(C24:N24) -> 9.5 | S24: =MIN(C24:N24) -> 4.3 | T24: =R24-S24 -> 5.2
B25: Shively | C25: 21.8 | D25: 17.7 | E25: 17.3 | F25: 16.5 | G25: 16.2 | H25: 14.6 | I25: 14.6 | J25: 14.4 | K25: X | L25: 12.9 | M25: 12.9 | N25: 13 | P25: =AVERAGE(C25:N25) -> 15.627273 | Q25: =STDEV(C25:N25) -> 2.677346 | R25: =MAX(C25:N25) -> 21.8 | S25: =MIN(C25:N25) -> 12.9 | T25: =R25-S25 -> 8.9
B26: Welker | C26: X | D26: X | E26: 12.7 | F26: 13.6 | G26: 15 | H26: 13.6 | I26: 9 | J26: 9.3 | K26: 10 | L26: 9.5 | M26: X | N26: 13.5 | P26: =AVERAGE(C26:N26) -> 11.8 | Q26: =STDEV(C26:N26) -> 2.3194827 | R26: =MAX(C26:N26) -> 15 | S26: =MIN(C26:N26) -> 9 | T26: =R26-S26 -> 6
B27: Zimmer | C27: X | D27: 14.3 | E27: 13 | F27: 11.9 | G27: 11.1 | H27: 9.9 | I27: 10.2 | J27: 10.4 | K27: 8.9 | L27: 10.2 | M27: 8.6 | N27: 7.5 | P27: =AVERAGE(C27:N27) -> 10.545455 | Q27: =STDEV(C27:N27) -> 1.9674164 | R27: =MAX(C27:N27) -> 14.3 | S27: =MIN(C27:N27) -> 7.5 | T27: =R27-S27 -> 6.8
B29: Average | C29: =AVERAGE(C3:C27) -> 20.438462 | D29: =AVERAGE(D3:D27) -> 16.611765 | E29: =AVERAGE(E3:E27) -> 15.158824 | F29: =AVERAGE(F3:F27) -> 13.92 | G29: =AVERAGE(G3:G27) -> 13.8 | H29: =AVERAGE(H3:H27) -> 13.257895 | I29: =AVERAGE(I3:I27) -> 11.995 | J29: =AVERAGE(J3:J27) -> 11.768421 | ... N29: =AVERAGE(N3:N27) -> 11.40625 | P29: =AVERAGE(P3:P27) -> 12.990267 | Q29: =AVERAGE(Q3:Q27) -> 2.2473845 | R29: =AVERAGE(R3:R27) -> 17.068 | S29: =AVERAGE(S3:S27) -> 10.328 | T29: =AVERAGE(T3:T27) -> 6.74
B30: Median | C30: =MEDIAN(C3:C27) -> 18.8 | D30: =MEDIAN(D3:D27) -> 16.4 | E30: =MEDIAN(E3:E27) -> 13.9 | F30: =MEDIAN(F3:F27) -> 13.9 | G30: =MEDIAN(G3:G27) -> 14.4 | H30: =MEDIAN(H3:H27) -> 13.6 | I30: =MEDIAN(I3:I27) -> 11.85 | J30: =MEDIAN(J3:J27) -> 10.7 | ... N30: =MEDIAN(N3:N27) -> 10.75 | P30: =MEDIAN(P3:P27) -> 11.942857 | Q30: =MEDIAN(Q3:Q27) -> 1.9313208 | R30: =MEDIAN(R3:R27) -> 15 | S30: =MEDIAN(S3:S27) -> 9.8 | T30: =MEDIAN(T3:T27) -> 4.8
B31: SD | C31: =STDEV(C3:C27) -> 6.8819254 | D31: =STDEV(D3:D27) -> 5.0163336 | E31: =STDEV(E3:E27) -> 5.258928 | F31: =STDEV(F3:F27) -> 5.0172964 | G31: =STDEV(G3:G27) -> 5.0490923 | H31: =STDEV(H3:H27) -> 4.7262054 | I31: =STDEV(I3:I27) -> 4.6172987 | J31: =STDEV(J3:J27) -> 4.6436399 | ... N31: =STDEV(N3:N27) -> 3.7436994

Sheet Points
A1: Points
A2: Aggregate | B2: =Handicaps!B2 -> Player | C2: Played | D2: FBC 1 | E2: FBC 2 | F2: FBC 3 | G2: FBC 4 | H2: FBC 5 | I2: FBC 6 | J2: FBC 7 | K2: FBC 8 | L2: FBC 9 | M2: FBC 10 | N2: FBC 11 | O2: FBC 12 | P2: FBC 13
B3: =Handicaps!B3 -> Cole | C3: =COUNT(D31:P31) | D3: =IF(COUNT($D31:D31)=0,"X",SUM($D31:D31)) -> X | E3: =IF(COUNT($D31:E31)=0,"X",SUM($D31:E31)) -> 0.5 | F3: =IF(COUNT($D31:F31)=0,"X",SUM($D31:F31)) -> 4 | G3: =IF(COUNT($D31:G31)=0,"X",SUM($D31:G31)) -> 6.5 | H3: =IF(COUNT($D31:H31)=0,"X",SUM($D31:H31)) -> 7.5 | I3: =IF(COUNT($D31:I31)=0,"X",SUM($D31:I31)) -> 11.5 | J3: =IF(COUNT($D31:J31)=0,"X",SUM($D31:J31)) -> 16 | K3: =IF(COUNT($D31:K31)=0,"X",SUM($D31:K31)) -> 19.5 | ... P3: =IF(COUNT($D31:P31)=0,"X",SUM($D31:P31))
B4: =Handicaps!B4 -> Connolly, B | C4: =COUNT(D32:P32) | D4: =IF(COUNT($D32:D32)=0,"X",SUM($D32:D32)) -> 6 | E4: =IF(COUNT($D32:E32)=0,"X",SUM($D32:E32)) -> 9.5 | F4: =IF(COUNT($D32:F32)=0,"X",SUM($D32:F32)) -> 14 | G4: =IF(COUNT($D32:G32)=0,"X",SUM($D32:G32)) -> 17.5 | H4: =IF(COUNT($D32:H32)=0,"X",SUM($D32:H32)) -> 21.5 | I4: =IF(COUNT($D32:I32)=0,"X",SUM($D32:I32)) -> 23.5 | J4: =IF(COUNT($D32:J32)=0,"X",SUM($D32:J32)) -> 25.5 | K4: =IF(COUNT($D32:K32)=0,"X",SUM($D32:K32)) -> 29.5 | ... P4: =IF(COUNT($D32:P32)=0,"X",SUM($D32:P32))
B5: Connolly, R | C5: =COUNT(D33:P33) | D5: =IF(COUNT($D33:D33)=0,"X",SUM($D33:D33)) -> X | E5: =IF(COUNT($D33:E33)=0,"X",SUM($D33:E33)) -> X | F5: =IF(COUNT($D33:F33)=0,"X",SUM($D33:F33)) -> X | G5: =IF(COUNT($D33:G33)=0,"X",SUM($D33:G33)) -> X | H5: =IF(COUNT($D33:H33)=0,"X",SUM($D33:H33)) -> X | I5: =IF(COUNT($D33:I33)=0,"X",SUM($D33:I33)) -> X | J5: =IF(COUNT($D33:J33)=0,"X",SUM($D33:J33)) -> X | K5: =IF(COUNT($D33:K33)=0,"X",SUM($D33:K33)) -> X | ... P5: =IF(COUNT($D33:P33)=0,"X",SUM($D33:P33))
B6: =Handicaps!B6 -> Connors | C6: =COUNT(D34:P34) | D6: =IF(COUNT($D34:D34)=0,"X",SUM($D34:D34)) -> X | E6: =IF(COUNT($D34:E34)=0,"X",SUM($D34:E34)) -> 2.5 | F6: =IF(COUNT($D34:F34)=0,"X",SUM($D34:F34)) -> 4.5 | G6: =IF(COUNT($D34:G34)=0,"X",SUM($D34:G34)) -> 8 | H6: =IF(COUNT($D34:H34)=0,"X",SUM($D34:H34)) -> 9 | I6: =IF(COUNT($D34:I34)=0,"X",SUM($D34:I34)) -> 11.5 | J6: =IF(COUNT($D34:J34)=0,"X",SUM($D34:J34)) -> 13 | K6: =IF(COUNT($D34:K34)=0,"X",SUM($D34:K34)) -> 15.5 | ... P6: =IF(COUNT($D34:P34)=0,"X",SUM($D34:P34))
B7: Delaney | C7: =COUNT(D35:P35) | D7: =IF(COUNT($D35:D35)=0,"X",SUM($D35:D35)) -> X | E7: =IF(COUNT($D35:E35)=0,"X",SUM($D35:E35)) -> X | F7: =IF(COUNT($D35:F35)=0,"X",SUM($D35:F35)) -> X | G7: =IF(COUNT($D35:G35)=0,"X",SUM($D35:G35)) -> X | H7: =IF(COUNT($D35:H35)=0,"X",SUM($D35:H35)) -> 4 | I7: =IF(COUNT($D35:I35)=0,"X",SUM($D35:I35)) -> 4 | J7: =IF(COUNT($D35:J35)=0,"X",SUM($D35:J35)) -> 4 | K7: =IF(COUNT($D35:K35)=0,"X",SUM($D35:K35)) -> 7 | ... P7: =IF(COUNT($D35:P35)=0,"X",SUM($D35:P35))
B8: Delneky | C8: =COUNT(D36:P36) | D8: =IF(COUNT($D36:D36)=0,"X",SUM($D36:D36)) -> X | E8: =IF(COUNT($D36:E36)=0,"X",SUM($D36:E36)) -> X | F8: =IF(COUNT($D36:F36)=0,"X",SUM($D36:F36)) -> X | G8: =IF(COUNT($D36:G36)=0,"X",SUM($D36:G36)) -> X | H8: =IF(COUNT($D36:H36)=0,"X",SUM($D36:H36)) -> X | I8: =IF(COUNT($D36:I36)=0,"X",SUM($D36:I36)) -> X | J8: =IF(COUNT($D36:J36)=0,"X",SUM($D36:J36)) -> X | K8: =IF(COUNT($D36:K36)=0,"X",SUM($D36:K36)) -> 1.5 | ... P8: =IF(COUNT($D36:P36)=0,"X",SUM($D36:P36))
B9: DeOteris | C9: =COUNT(D37:P37) | D9: =IF(COUNT($D37:D37)=0,"X",SUM($D37:D37)) -> X | E9: =IF(COUNT($D37:E37)=0,"X",SUM($D37:E37)) -> X | F9: =IF(COUNT($D37:F37)=0,"X",SUM($D37:F37)) -> X | G9: =IF(COUNT($D37:G37)=0,"X",SUM($D37:G37)) -> X | H9: =IF(COUNT($D37:H37)=0,"X",SUM($D37:H37)) -> X | I9: =IF(COUNT($D37:I37)=0,"X",SUM($D37:I37)) -> X | J9: =IF(COUNT($D37:J37)=0,"X",SUM($D37:J37)) -> X | K9: =IF(COUNT($D37:K37)=0,"X",SUM($D37:K37)) -> 3 | ... P9: =IF(COUNT($D37:P37)=0,"X",SUM($D37:P37))
B10: =Handicaps!B10 -> Ferrin | C10: =COUNT(D38:P38) | D10: =IF(COUNT($D38:D38)=0,"X",SUM($D38:D38)) -> 5.5 | E10: =IF(COUNT($D38:E38)=0,"X",SUM($D38:E38)) -> 8 | F10: =IF(COUNT($D38:F38)=0,"X",SUM($D38:F38)) -> 13 | G10: =IF(COUNT($D38:G38)=0,"X",SUM($D38:G38)) -> 15.5 | H10: =IF(COUNT($D38:H38)=0,"X",SUM($D38:H38)) -> 20 | I10: =IF(COUNT($D38:I38)=0,"X",SUM($D38:I38)) -> 23 | J10: =IF(COUNT($D38:J38)=0,"X",SUM($D38:J38)) -> 27.5 | K10: =IF(COUNT($D38:K38)=0,"X",SUM($D38:K38)) -> 31 | ... P10: =IF(COUNT($D38:P38)=0,"X",SUM($D38:P38))
B11: =Handicaps!B11 -> Flanders | C11: =COUNT(D39:P39) | D11: =IF(COUNT($D39:D39)=0,"X",SUM($D39:D39)) -> 2 | E11: =IF(COUNT($D39:E39)=0,"X",SUM($D39:E39)) -> 3.5 | F11: =IF(COUNT($D39:F39)=0,"X",SUM($D39:F39)) -> 4 | G11: =IF(COUNT($D39:G39)=0,"X",SUM($D39:G39)) -> 9.5 | H11: =IF(COUNT($D39:H39)=0,"X",SUM($D39:H39)) -> 12.5 | I11: =IF(COUNT($D39:I39)=0,"X",SUM($D39:I39)) -> 15.5 | J11: =IF(COUNT($D39:J39)=0,"X",SUM($D39:J39)) -> 19.5 | K11: =IF(COUNT($D39:K39)=0,"X",SUM($D39:K39)) -> 22.5 | ... P11: =IF(COUNT($D39:P39)=0,"X",SUM($D39:P39))
B12: =Handicaps!B12 -> Fogan | C12: =COUNT(D40:P40) | D12: =IF(COUNT($D40:D40)=0,"X",SUM($D40:D40)) -> X | E12: =IF(COUNT($D40:E40)=0,"X",SUM($D40:E40)) -> 2 | F12: =IF(COUNT($D40:F40)=0,"X",SUM($D40:F40)) -> 5 | G12: =IF(COUNT($D40:G40)=0,"X",SUM($D40:G40)) -> 8 | H12: =IF(COUNT($D40:H40)=0,"X",SUM($D40:H40)) -> 9 | I12: =IF(COUNT($D40:I40)=0,"X",SUM($D40:I40)) -> 9.5 | J12: =IF(COUNT($D40:J40)=0,"X",SUM($D40:J40)) -> 12.5 | K12: =IF(COUNT($D40:K40)=0,"X",SUM($D40:K40)) -> 15.5 | ... P12: =IF(COUNT($D40:P40)=0,"X",SUM($D40:P40))
B13: =Handicaps!B13 -> Forster | C13: =COUNT(D41:P41) | D13: =IF(COUNT($D41:D41)=0,"X",SUM($D41:D41)) -> X | E13: =IF(COUNT($D41:E41)=0,"X",SUM($D41:E41)) -> 5.5 | F13: =IF(COUNT($D41:F41)=0,"X",SUM($D41:F41)) -> 9 | G13: =IF(COUNT($D41:G41)=0,"X",SUM($D41:G41)) -> 14.5 | H13: =IF(COUNT($D41:H41)=0,"X",SUM($D41:H41)) -> 19.5 | I13: =IF(COUNT($D41:I41)=0,"X",SUM($D41:I41)) -> 24.5 | J13: =IF(COUNT($D41:J41)=0,"X",SUM($D41:J41)) -> 29 | K13: =IF(COUNT($D41:K41)=0,"X",SUM($D41:K41)) -> 30 | ... P13: =IF(COUNT($D41:P41)=0,"X",SUM($D41:P41))
B14: =Handicaps!B14 -> Gray | C14: =COUNT(D42:P42) | D14: =IF(COUNT($D42:D42)=0,"X",SUM($D42:D42)) -> X | E14: =IF(COUNT($D42:E42)=0,"X",SUM($D42:E42)) -> X | F14: =IF(COUNT($D42:F42)=0,"X",SUM($D42:F42)) -> 4 | G14: =IF(COUNT($D42:G42)=0,"X",SUM($D42:G42)) -> 8 | H14: =IF(COUNT($D42:H42)=0,"X",SUM($D42:H42)) -> 11.5 | I14: =IF(COUNT($D42:I42)=0,"X",SUM($D42:I42)) -> 16 | J14: =IF(COUNT($D42:J42)=0,"X",SUM($D42:J42)) -> 23 | K14: =IF(COUNT($D42:K42)=0,"X",SUM($D42:K42)) -> 23 | ... P14: =IF(COUNT($D42:P42)=0,"X",SUM($D42:P42))
B15: =Handicaps!B15 -> Grise | C15: =COUNT(D43:P43) | D15: =IF(COUNT($D43:D43)=0,"X",SUM($D43:D43)) -> 2.5 | E15: =IF(COUNT($D43:E43)=0,"X",SUM($D43:E43)) -> 7.5 | F15: =IF(COUNT($D43:F43)=0,"X",SUM($D43:F43)) -> 8.5 | G15: =IF(COUNT($D43:G43)=0,"X",SUM($D43:G43)) -> 13.5 | H15: =IF(COUNT($D43:H43)=0,"X",SUM($D43:H43)) -> 16 | I15: =IF(COUNT($D43:I43)=0,"X",SUM($D43:I43)) -> 20.5 | J15: =IF(COUNT($D43:J43)=0,"X",SUM($D43:J43)) -> 27 | K15: =IF(COUNT($D43:K43)=0,"X",SUM($D43:K43)) -> 31.5 | ... P15: =IF(COUNT($D43:P43)=0,"X",SUM($D43:P43))
B16: =Handicaps!B16 -> Hilts | C16: =COUNT(D44:P44) | D16: =IF(COUNT($D44:D44)=0,"X",SUM($D44:D44)) -> 2.5 | E16: =IF(COUNT($D44:E44)=0,"X",SUM($D44:E44)) -> 4.5 | F16: =IF(COUNT($D44:F44)=0,"X",SUM($D44:F44)) -> 7 | G16: =IF(COUNT($D44:G44)=0,"X",SUM($D44:G44)) -> 7 | H16: =IF(COUNT($D44:H44)=0,"X",SUM($D44:H44)) -> 10 | I16: =IF(COUNT($D44:I44)=0,"X",SUM($D44:I44)) -> 13.5 | J16: =IF(COUNT($D44:J44)=0,"X",SUM($D44:J44)) -> 15.5 | K16: =IF(COUNT($D44:K44)=0,"X",SUM($D44:K44)) -> 20.5 | ... P16: =IF(COUNT($D44:P44)=0,"X",SUM($D44:P44))
B17: =Handicaps!B17 -> Jackson | C17: =COUNT(D45:P45) | D17: =IF(COUNT($D45:D45)=0,"X",SUM($D45:D45)) -> 3.5 | E17: =IF(COUNT($D45:E45)=0,"X",SUM($D45:E45)) -> 9.5 | F17: =IF(COUNT($D45:F45)=0,"X",SUM($D45:F45)) -> 14.5 | G17: =IF(COUNT($D45:G45)=0,"X",SUM($D45:G45)) -> 17 | H17: =IF(COUNT($D45:H45)=0,"X",SUM($D45:H45)) -> 20.5 | I17: =IF(COUNT($D45:I45)=0,"X",SUM($D45:I45)) -> 27 | J17: =IF(COUNT($D45:J45)=0,"X",SUM($D45:J45)) -> 31 | K17: =IF(COUNT($D45:K45)=0,"X",SUM($D45:K45)) -> 33.5 | ... P17: =IF(COUNT($D45:P45)=0,"X",SUM($D45:P45))
B18: =Handicaps!B18 -> Lynch | C18: =COUNT(D46:P46) | D18: =IF(COUNT($D46:D46)=0,"X",SUM($D46:D46)) -> 1.5 | E18: =IF(COUNT($D46:E46)=0,"X",SUM($D46:E46)) -> 5.5 | F18: =IF(COUNT($D46:F46)=0,"X",SUM($D46:F46)) -> 9.5 | G18: =IF(COUNT($D46:G46)=0,"X",SUM($D46:G46)) -> 13.5 | H18: =IF(COUNT($D46:H46)=0,"X",SUM($D46:H46)) -> 17 | I18: =IF(COUNT($D46:I46)=0,"X",SUM($D46:I46)) -> 18.5 | J18: =IF(COUNT($D46:J46)=0,"X",SUM($D46:J46)) -> 23 | K18: =IF(COUNT($D46:K46)=0,"X",SUM($D46:K46)) -> 27 | ... P18: =IF(COUNT($D46:P46)=0,"X",SUM($D46:P46))
B19: =Handicaps!B19 -> Mangold | C19: =COUNT(D47:P47) | D19: =IF(COUNT($D47:D47)=0,"X",SUM($D47:D47)) -> 0 | E19: =IF(COUNT($D47:E47)=0,"X",SUM($D47:E47)) -> 3.5 | F19: =IF(COUNT($D47:F47)=0,"X",SUM($D47:F47)) -> 6.5 | G19: =IF(COUNT($D47:G47)=0,"X",SUM($D47:G47)) -> 8.5 | H19: =IF(COUNT($D47:H47)=0,"X",SUM($D47:H47)) -> 13.5 | I19: =IF(COUNT($D47:I47)=0,"X",SUM($D47:I47)) -> 14.5 | J19: =IF(COUNT($D47:J47)=0,"X",SUM($D47:J47)) -> 17 | K19: =IF(COUNT($D47:K47)=0,"X",SUM($D47:K47)) -> 18 | ... P19: =IF(COUNT($D47:P47)=0,"X",SUM($D47:P47))
B20: =Handicaps!B20 -> McInerney | C20: =COUNT(D48:P48) | D20: =IF(COUNT($D48:D48)=0,"X",SUM($D48:D48)) -> X | E20: =IF(COUNT($D48:E48)=0,"X",SUM($D48:E48)) -> X | F20: =IF(COUNT($D48:F48)=0,"X",SUM($D48:F48)) -> 2.5 | G20: =IF(COUNT($D48:G48)=0,"X",SUM($D48:G48)) -> 6 | H20: =IF(COUNT($D48:H48)=0,"X",SUM($D48:H48)) -> 9.5 | I20: =IF(COUNT($D48:I48)=0,"X",SUM($D48:I48)) -> 15 | J20: =IF(COUNT($D48:J48)=0,"X",SUM($D48:J48)) -> 18 | K20: =IF(COUNT($D48:K48)=0,"X",SUM($D48:K48)) -> 21 | ... P20: =IF(COUNT($D48:P48)=0,"X",SUM($D48:P48))
B21: =Handicaps!B21 -> Norat | C21: =COUNT(D49:P49) | D21: =IF(COUNT($D49:D49)=0,"X",SUM($D49:D49)) -> X | E21: =IF(COUNT($D49:E49)=0,"X",SUM($D49:E49)) -> X | F21: =IF(COUNT($D49:F49)=0,"X",SUM($D49:F49)) -> 2.5 | G21: =IF(COUNT($D49:G49)=0,"X",SUM($D49:G49)) -> 4.5 | H21: =IF(COUNT($D49:H49)=0,"X",SUM($D49:H49)) -> 10 | I21: =IF(COUNT($D49:I49)=0,"X",SUM($D49:I49)) -> 14 | J21: =IF(COUNT($D49:J49)=0,"X",SUM($D49:J49)) -> 16 | K21: =IF(COUNT($D49:K49)=0,"X",SUM($D49:K49)) -> 16 | ... P21: =IF(COUNT($D49:P49)=0,"X",SUM($D49:P49))
B22: Perkins | C22: =COUNT(D50:P50) | D22: =IF(COUNT($D50:D50)=0,"X",SUM($D50:D50)) -> X | E22: =IF(COUNT($D50:E50)=0,"X",SUM($D50:E50)) -> X | F22: =IF(COUNT($D50:F50)=0,"X",SUM($D50:F50)) -> X | G22: =IF(COUNT($D50:G50)=0,"X",SUM($D50:G50)) -> X | H22: =IF(COUNT($D50:H50)=0,"X",SUM($D50:H50)) -> X | I22: =IF(COUNT($D50:I50)=0,"X",SUM($D50:I50)) -> X | J22: =IF(COUNT($D50:J50)=0,"X",SUM($D50:J50)) -> X | K22: =IF(COUNT($D50:K50)=0,"X",SUM($D50:K50)) -> 5.5 | ... P22: =IF(COUNT($D50:P50)=0,"X",SUM($D50:P50))
B23: Piegari | C23: =COUNT(D51:P51) | D23: =IF(COUNT($D51:D51)=0,"X",SUM($D51:D51)) -> X | E23: =IF(COUNT($D51:E51)=0,"X",SUM($D51:E51)) -> X | F23: =IF(COUNT($D51:F51)=0,"X",SUM($D51:F51)) -> X | G23: =IF(COUNT($D51:G51)=0,"X",SUM($D51:G51)) -> X | H23: =IF(COUNT($D51:H51)=0,"X",SUM($D51:H51)) -> X | I23: =IF(COUNT($D51:I51)=0,"X",SUM($D51:I51)) -> X | J23: =IF(COUNT($D51:J51)=0,"X",SUM($D51:J51)) -> X | K23: =IF(COUNT($D51:K51)=0,"X",SUM($D51:K51)) -> 1.5 | ... P23: =IF(COUNT($D51:P51)=0,"X",SUM($D51:P51))
B24: =Handicaps!B24 -> Poirier | C24: =COUNT(D52:P52) | D24: =IF(COUNT($D52:D52)=0,"X",SUM($D52:D52)) -> 3.5 | E24: =IF(COUNT($D52:E52)=0,"X",SUM($D52:E52)) -> 3.5 | F24: =IF(COUNT($D52:F52)=0,"X",SUM($D52:F52)) -> 3.5 | G24: =IF(COUNT($D52:G52)=0,"X",SUM($D52:G52)) -> 3.5 | H24: =IF(COUNT($D52:H52)=0,"X",SUM($D52:H52)) -> 7 | I24: =IF(COUNT($D52:I52)=0,"X",SUM($D52:I52)) -> 7 | J24: =IF(COUNT($D52:J52)=0,"X",SUM($D52:J52)) -> 11.5 | K24: =IF(COUNT($D52:K52)=0,"X",SUM($D52:K52)) -> 11.5 | ... P24: =IF(COUNT($D52:P52)=0,"X",SUM($D52:P52))
B25: =Handicaps!B25 -> Shively | C25: =COUNT(D53:P53) | D25: =IF(COUNT($D53:D53)=0,"X",SUM($D53:D53)) -> 4 | E25: =IF(COUNT($D53:E53)=0,"X",SUM($D53:E53)) -> 7 | F25: =IF(COUNT($D53:F53)=0,"X",SUM($D53:F53)) -> 8.5 | G25: =IF(COUNT($D53:G53)=0,"X",SUM($D53:G53)) -> 11 | H25: =IF(COUNT($D53:H53)=0,"X",SUM($D53:H53)) -> 11.5 | I25: =IF(COUNT($D53:I53)=0,"X",SUM($D53:I53)) -> 17 | J25: =IF(COUNT($D53:J53)=0,"X",SUM($D53:J53)) -> 20.5 | K25: =IF(COUNT($D53:K53)=0,"X",SUM($D53:K53)) -> 23 | ... P25: =IF(COUNT($D53:P53)=0,"X",SUM($D53:P53))
B26: =Handicaps!B26 -> Welker | C26: =COUNT(D54:P54) | D26: =IF(COUNT($D54:D54)=0,"X",SUM($D54:D54)) -> X | E26: =IF(COUNT($D54:E54)=0,"X",SUM($D54:E54)) -> X | F26: =IF(COUNT($D54:F54)=0,"X",SUM($D54:F54)) -> X | G26: =IF(COUNT($D54:G54)=0,"X",SUM($D54:G54)) -> 2 | H26: =IF(COUNT($D54:H54)=0,"X",SUM($D54:H54)) -> 5 | I26: =IF(COUNT($D54:I54)=0,"X",SUM($D54:I54)) -> 10.5 | J26: =IF(COUNT($D54:J54)=0,"X",SUM($D54:J54)) -> 13.5 | K26: =IF(COUNT($D54:K54)=0,"X",SUM($D54:K54)) -> 16.5 | ... P26: =IF(COUNT($D54:P54)=0,"X",SUM($D54:P54))
B27: =Handicaps!B27 -> Zimmer | C27: =COUNT(D55:P55) | D27: =IF(COUNT($D55:D55)=0,"X",SUM($D55:D55)) -> X | E27: =IF(COUNT($D55:E55)=0,"X",SUM($D55:E55)) -> X | F27: =IF(COUNT($D55:F55)=0,"X",SUM($D55:F55)) -> 4 | G27: =IF(COUNT($D55:G55)=0,"X",SUM($D55:G55)) -> 8 | H27: =IF(COUNT($D55:H55)=0,"X",SUM($D55:H55)) -> 12.5 | I27: =IF(COUNT($D55:I55)=0,"X",SUM($D55:I55)) -> 13.5 | J27: =IF(COUNT($D55:J55)=0,"X",SUM($D55:J55)) -> 19.5 | K27: =IF(COUNT($D55:K55)=0,"X",SUM($D55:K55)) -> 24 | ... P27: =IF(COUNT($D55:P55)=0,"X",SUM($D55:P55))
A29: Per Cup | B29: Player | D29: =D2 -> FBC 1 | E29: =E2 -> FBC 2 | F29: =F2 -> FBC 3 | G29: =G2 -> FBC 4 | H29: =H2 -> FBC 5 | I29: =I2 -> FBC 6 | J29: =J2 -> FBC 7 | K29: =K2 -> FBC 8 | ... N29: =N2 -> FBC 11 | O29: FBC 12 | P29: =P2 -> FBC 13 | Q29: Total | R29: Best Cup | S29: Worst Cup | T29: Average | U29: Delta
D30: Saratoga | E30: Turning Stone | F30: Sea Island I | G30: French Lick | H30: Hilton Head | I30: Arcadia Blufs | J30: Pebble Beach | K30: Sand Valley | L30: Sea Island II | M30: Dublin | N30: Pinehurst | O30: Killarney | P30: Frisco
B31: =B3 -> Cole | D31: X | E31: 0.5 | F31: 3.5 | G31: 2.5 | H31: 1 | I31: 4 | J31: 4.5 | K31: 3.5 | L31: 2.5 | M31: 4.5 | N31: 3.5 | O31: X | P31: 4 | Q31: =SUM(D31:P31) | R31: =MAX(D31:P31) | S31: =MIN(D31:P31) | T31: =AVERAGE(D31:P31) | U31: =R31-S31 -> 4
B32: =B4 -> Connolly, B | D32: 6 | E32: 3.5 | F32: 4.5 | G32: 3.5 | H32: 4 | I32: 2 | J32: 2 | K32: 4 | L32: 3.5 | M32: 6 | N32: 5 | O32: 6.5 | P32: 2 | Q32: =SUM(D32:P32) | R32: =MAX(D32:P32) | S32: =MIN(D32:P32) | T32: =AVERAGE(D32:P32) | U32: =R32-S32 -> 4.5
B33: Connolly, R | D33: X | E33: X | F33: X | G33: X | H33: X | I33: X | J33: X | K33: X | L33: X | M33: 3 | N33: X | O33: 6 | P33: 1.5 | Q33: =SUM(D33:P33) | R33: =MAX(D33:P33) | S33: =MIN(D33:P33) | T33: =AVERAGE(D33:P33) | U33: =R33-S33 -> 3
B34: =B6 -> Connors | D34: X | E34: 2.5 | F34: 2 | G34: 3.5 | H34: 1 | I34: 2.5 | J34: 1.5 | K34: 2.5 | L34: 1 | M34: 3 | N34: 2.5 | O34: X | P34: X | Q34: =SUM(D34:P34) | R34: =MAX(D34:P34) | S34: =MIN(D34:P34) | T34: =AVERAGE(D34:P34) | U34: =R34-S34 -> 2.5
B35: Delaney | D35: X | E35: X | F35: X | G35: X | H35: 4 | I35: X | J35: X | K35: 3 | L35: 3 | M35: 2 | N35: 2.5 | O35: 4 | P35: 4 | Q35: =SUM(D35:P35) | R35: =MAX(D35:P35) | S35: =MIN(D35:P35) | T35: =AVERAGE(D35:P35) | U35: =R35-S35 -> 2
B36: Delneky | D36: X | E36: X | F36: X | G36: X | H36: X | I36: X | J36: X | K36: 1.5 | L36: 4.5 | M36: 5 | N36: 4.5 | O36: 5 | P36: 4 | Q36: =SUM(D36:P36) | R36: =MAX(D36:P36) | S36: =MIN(D36:P36) | T36: =AVERAGE(D36:P36) | U36: =R36-S36 -> 3.5
B37: DeOteris | D37: X | E37: X | F37: X | G37: X | H37: X | I37: X | J37: X | K37: 3 | L37: 3 | M37: X | N37: X | O37: 1 | P37: 2.5 | Q37: =SUM(D37:P37) | R37: =MAX(D37:P37) | S37: =MIN(D37:P37) | T37: =AVERAGE(D37:P37) | U37: =R37-S37 -> 2
B38: =B10 -> Ferrin | D38: 5.5 | E38: 2.5 | F38: 5 | G38: 2.5 | H38: 4.5 | I38: 3 | J38: 4.5 | K38: 3.5 | L38: 2.5 | M38: 4 | N38: 5 | O38: 3.5 | P38: 4.5 | Q38: =SUM(D38:P38) | R38: =MAX(D38:P38) | S38: =MIN(D38:P38) | T38: =AVERAGE(D38:P38) | U38: =R38-S38 -> 3
B39: =B11 -> Flanders | D39: 2 | E39: 1.5 | F39: 0.5 | G39: 5.5 | H39: 3 | I39: 3 | J39: 4 | K39: 3 | L39: 2 | M39: 4 | N39: 1.5 | O39: 6.5 | P39: 5 | Q39: =SUM(D39:P39) | R39: =MAX(D39:P39) | S39: =MIN(D39:P39) | T39: =AVERAGE(D39:P39) | U39: =R39-S39 -> 6
B40: =B12 -> Fogan | D40: X | E40: 2 | F40: 3 | G40: 3 | H40: 1 | I40: 0.5 | J40: 3 | K40: 3 | L40: 4.5 | M40: 1.5 | N40: 4.5 | O40: 4 | P40: 3 | Q40: =SUM(D40:P40) | R40: =MAX(D40:P40) | S40: =MIN(D40:P40) | T40: =AVERAGE(D40:P40) | U40: =R40-S40 -> 4
B41: =B13 -> Forster | D41: X | E41: 5.5 | F41: 3.5 | G41: 5.5 | H41: 5 | I41: 5 | J41: 4.5 | K41: 1 | L41: 4.5 | M41: 0 | N41: 3.5 | O41: 4 | P41: 4.5 | Q41: =SUM(D41:P41) | R41: =MAX(D41:P41) | S41: =MIN(D41:P41) | T41: =AVERAGE(D41:P41) | U41: =R41-S41 -> 5.5
...

Sheet Cups
B2: =Handicaps!B2 -> Player | C2: FBC 1 | D2: FBC 2 | E2: FBC 3 | F2: FBC 4 | G2: FBC 5 | H2: FBC 6 | I2: FBC 7 | J2: FBC 8 | K2: FBC 9 | L2: FBC 10 | M2: FBC 11 | N2: FBC 12 | O2: FBC 13 | P2: Total | Q2: Played | R2: % | S2: Lost
B3: Lynch | C3: 1 | D3: 1 | E3: 1 | F3: 1 | G3: 1 | H3: 1 | I3: 1 | J3: 0 | K3: 1 | L3: 1 | M3: 0 | N3: 1 | O3: 0 | P3: =SUM(C3:O3) | Q3: =VLOOKUP($B3,Points!$B$2:$C$34,2,FALSE()) | R3: =P3/Q3 | S3: =Q3-P3
B4: Connolly, B | C4: 1 | D4: 1 | E4: 1 | F4: 1 | G4: 1 | H4: 0 | I4: 0 | J4: 1 | K4: 1 | L4: 1 | M4: 1 | N4: 0 | O4: 1 | P4: =SUM(C4:O4) | Q4: =VLOOKUP($B4,Points!$B$2:$C$34,2,FALSE()) | R4: =P4/Q4 | S4: =Q4-P4
B5: Grise | C5: 0 | D5: 1 | E5: 0 | F5: 1 | G5: 1 | H5: 1 | I5: 1 | J5: 1 | K5: 0 | L5: 1 | M5: 0 | N5: 1 | O5: 1 | P5: =SUM(C5:O5) | Q5: =VLOOKUP($B5,Points!$B$2:$C$34,2,FALSE()) | R5: =P5/Q5 | S5: =Q5-P5
B6: Hilts | C6: 1 | D6: 1 | E6: 1 | F6: X | G6: 0 | H6: 1 | I6: 0 | J6: 1 | K6: 1 | L6: 1 | M6: 0 | N6: 1 | O6: 1 | P6: =SUM(C6:O6) | Q6: =VLOOKUP($B6,Points!$B$2:$C$34,2,FALSE()) | R6: =P6/Q6 | S6: =Q6-P6
B7: Shively | C7: 1 | D7: 0 | E7: 0 | F7: 1 | G7: 1 | H7: 1 | I7: 0 | J7: 0 | K7: 1 | L7: X | M7: 1 | N7: 1 | O7: 0 | P7: =SUM(C7:O7) | Q7: =VLOOKUP($B7,Points!$B$2:$C$34,2,FALSE()) | R7: =P7/Q7 | S7: =Q7-P7
B8: Zimmer | C8: X | D8: X | E8: 1 | F8: 1 | G8: 1 | H8: 0 | I8: 1 | J8: 1 | K8: 0 | L8: 0 | M8: 1 | N8: 0 | O8: 1 | P8: =SUM(C8:O8) | Q8: =VLOOKUP($B8,Points!$B$2:$C$34,2,FALSE()) | R8: =P8/Q8 | S8: =Q8-P8
B9: McInerney | C9: X | D9: X | E9: 1 | F9: 1 | G9: 1 | H9: 1 | I9: 0 | J9: 0 | K9: 1 | L9: 0 | M9: X | N9: X | O9: 0 | P9: =SUM(C9:O9) | Q9: =VLOOKUP($B9,Points!$B$2:$C$34,2,FALSE()) | R9: =P9/Q9 | S9: =Q9-P9
B10: Flanders | C10: 0 | D10: 1 | E10: 0 | F10: 0 | G10: 0 | H10: 0 | I10: 1 | J10: 0 | K10: 1 | L10: 1 | M10: 0 | N10: 1 | O10: 1 | P10: =SUM(C10:O10) | Q10: =VLOOKUP($B10,Points!$B$2:$C$34,2,FALSE()) | R10: =P10/Q10 | S10: =Q10-P10
B11: Fogan | C11: X | D11: 0 | E11: 1 | F11: 1 | G11: 0 | H11: 1 | I11: 0 | J11: 0 | K11: 0 | L11: 0 | M11: 1 | N11: 0 | O11: 0 | P11: =SUM(C11:O11) | Q11: =VLOOKUP($B11,Points!$B$2:$C$34,2,FALSE()) | R11: =P11/Q11 | S11: =Q11-P11
B12: Connors | C12: X | D12: 1 | E12: 0 | F12: 0 | G12: 0 | H12: 0 | I12: 1 | J12: 1 | K12: 1 | L12: 0 | M12: 0 | N12: X | O12: X | P12: =SUM(C12:O12) | Q12: =VLOOKUP($B12,Points!$B$2:$C$34,2,FALSE()) | R12: =P12/Q12 | S12: =Q12-P12
B13: Cole | C13: X | D13: 0 | E13: 1 | F13: 0 | G13: 0 | H13: 0 | I13: 1 | J13: 0 | K13: 1 | L13: 1 | M13: 0 | N13: X | O13: 1 | P13: =SUM(C13:O13) | Q13: =VLOOKUP($B13,Points!$B$2:$C$34,2,FALSE()) | R13: =P13/Q13 | S13: =Q13-P13
B14: Delaney | C14: X | D14: X | E14: X | F14: X | G14: 1 | H14: X | I14: X | J14: 1 | K14: 1 | L14: 1 | M14: 0 | N14: 0 | O14: 1 | P14: =SUM(C14:O14) | Q14: =VLOOKUP($B14,Points!$B$2:$C$34,2,FALSE()) | R14: =P14/Q14 | S14: =Q14-P14
B15: Gray | C15: X | D15: X | E15: 1 | F15: 0 | G15: 0 | H15: 1 | I15: 1 | J15: X | K15: X | L15: 0 | M15: 1 | N15: X | O15: 0 | P15: =SUM(C15:O15) | Q15: =VLOOKUP($B15,Points!$B$2:$C$34,2,FALSE()) | R15: =P15/Q15 | S15: =Q15-P15
B16: Ferrin | C16: 0 | D16: 0 | E16: 0 | F16: 0 | G16: 0 | H16: 0 | I16: 1 | J16: 1 | K16: 0 | L16: 1 | M16: 1 | N16: 0 | O16: 0 | P16: =SUM(C16:O16) | Q16: =VLOOKUP($B16,Points!$B$2:$C$34,2,FALSE()) | R16: =P16/Q16 | S16: =Q16-P16
B17: Perkins | C17: X | D17: X | E17: X | F17: X | G17: X | H17: X | I17: X | J17: 1 | K17: 1 | L17: 1 | M17: X | N17: 1 | O17: 0 | P17: =SUM(C17:O17) | Q17: =VLOOKUP($B17,Points!$B$2:$C$34,2,FALSE()) | R17: =P17/Q17 | S17: =Q17-P17
B18: Forster | C18: X | D18: 1 | E18: 0 | F18: 0 | G18: 1 | H18: 0 | I18: 0 | J18: 0 | K18: 0 | L18: 0 | M18: 1 | N18: 1 | O18: 1 | P18: =SUM(C18:O18) | Q18: =VLOOKUP($B18,Points!$B$2:$C$34,2,FALSE()) | R18: =P18/Q18 | S18: =Q18-P18
B19: Bussiculo | C19: X | D19: 0 | E19: 0 | F19: 1 | G19: 0 | H19: 1 | I19: 1 | J19: X | K19: X | L19: X | M19: X | N19: X | O19: X | P19: =SUM(C19:O19) | Q19: 6 | R19: =P19/Q19 | S19: =Q19-P19
B20: Jackson | C20: 0 | D20: 1 | E20: 0 | F20: 0 | G20: 0 | H20: 1 | I20: 1 | J20: 0 | K20: 0 | L20: 0 | M20: 0 | N20: 0 | O20: 0 | P20: =SUM(C20:O20) | Q20: =VLOOKUP($B20,Points!$B$2:$C$34,2,FALSE()) | R20: =P20/Q20 | S20: =Q20-P20
B21: Mangold | C21: 0 | D21: 0 | E21: 0 | F21: 0 | G21: 1 | H21: 1 | I21: 0 | J21: 0 | K21: X | L21: 0 | M21: 0 | N21: 1 | O21: 0 | P21: =SUM(C21:O21) | Q21: =VLOOKUP($B21,Points!$B$2:$C$34,2,FALSE()) | R21: =P21/Q21 | S21: =Q21-P21
B22: Poirier | C22: 1 | D22: X | E22: X | F22: X | G22: 0 | H22: 0 | I22: 0 | J22: X | K22: 0 | L22: X | M22: 1 | N22: 1 | O22: 1 | P22: =SUM(C22:O22) | Q22: =VLOOKUP($B22,Points!$B$2:$C$34,2,FALSE()) | R22: =P22/Q22 | S22: =Q22-P22
B23: Hickerson | C23: 0 | D23: 0 | E23: 1 | F23: 1 | G23: X | H23: X | I23: X | J23: X | K23: X | L23: X | M23: X | N23: X | O23: X | P23: =SUM(C23:O23) | Q23: 4 | R23: =P23/Q23 | S23: =Q23-P23
B24: Welker | C24: X | D24: X | E24: X | F24: 1 | G24: 0 | H24: 0 | I24: 0 | J24: 1 | K24: 0 | L24: 0 | M24: 0 | N24: X | O24: 0 | P24: =SUM(C24:O24) | Q24: =VLOOKUP($B24,Points!$B$2:$C$34,2,FALSE()) | R24: =P24/Q24 | S24: =Q24-P24
B25: Delneky | C25: X | D25: X | E25: X | F25: X | G25: X | H25: X | I25: X | J25: 1 | K25: 0 | L25: 0 | M25: 1 | N25: 0 | O25: 1 | P25: =SUM(C25:O25) | Q25: =VLOOKUP($B25,Points!$B$2:$C$34,2,FALSE()) | R25: =P25/Q25 | S25: =Q25-P25
B26: Norat | C26: X | D26: 0 | E26: 0 | F26: 0 | G26: 1 | H26: 0 | I26: 0 | J26: X | K26: X | L26: X | M26: 1 | N26: X | O26: 1 | P26: =SUM(C26:O26) | Q26: =VLOOKUP($B26,Points!$B$2:$C$34,2,FALSE()) | R26: =P26/Q26 | S26: =Q26-P26
B27: DeOteris | C27: X | D27: X | E27: X | F27: X | G27: X | H27: X | I27: X | J27: 1 | K27: 0 | L27: X | M27: X | N27: 0 | O27: 0 | P27: =SUM(C27:O27) | Q27: =VLOOKUP($B27,Points!$B$2:$C$34,2,FALSE()) | R27: =P27/Q27 | S27: =Q27-P27
B28: Macklin | C28: 1 | D28: X | E28: X | F28: X | G28: X | H28: X | I28: X | J28: X | K28: X | L28: X | M28: X | N28: X | O28: X | P28: =SUM(C28:O28) | Q28: 1 | R28: =P28/Q28 | S28: =Q28-P28
B29: Weisberger | C29: X | D29: 0 | E29: 1 | F29: X | G29: X | H29: X | I29: X | J29: X | K29: X | L29: X | M29: X | N29: X | O29: X | P29: =SUM(C29:O29) | Q29: 3 | R29: =P29/Q29 | S29: =Q29-P29
B30: Connolly, R | C30: X | D30: X | E30: X | F30: X | G30: X | H30: X | I30: X | J30: X | K30: X | L30: 1 | M30: X | N30: 0 | O30: 1 | P30: =SUM(C30:O30) | Q30: =VLOOKUP($B30,Points!$B$2:$C$34,2,FALSE()) | R30: =P30/Q30 | S30: =Q30-P30
B31: Snyder | C31: X | D31: X | E31: X | F31: X | G31: X | H31: X | I31: X | J31: X | K31: X | L31: X | M31: X | N31: 1 | O31: X | P31: =SUM(C31:O31) | Q31: 1 | R31: =P31/Q31 | S31: =Q31-P31
B32: Piegari | C32: X | D32: X | E32: X | F32: X | G32: X | H32: X | I32: X | J32: 0 | K32: X | L32: X | M32: X | N32: 0 | O32: 0 | P32: =SUM(C32:O32) | Q32: =VLOOKUP($B32,Points!$B$2:$C$34,2,FALSE()) | R32: =P32/Q32 | S32: =Q32-P32
B33: Ramsay | C33: X | D33: X | E33: X | F33: X | G33: X | H33: X | I33: X | J33: 0 | K33: X | L33: X | M33: X | N33: X | O33: X | P33: X
B34: Total | C34: =SUM(C3:C33) -> 6 | D34: =SUM(D3:D33) -> 8 | E34: =SUM(E3:E33) -> 10 | F34: =SUM(F3:F33) -> 10 | G34: =SUM(G3:G33) -> 10 | H34: =SUM(H3:H33) -> 10 | I34: =SUM(I3:I33) -> 10 | J34: =SUM(J3:J33) -> 11 | ... Q34: =SUM(Q3:Q33)
